Workbook

Sheet 3차년도 전체요약
A1: 3차년도 예산 관리 현황
B2: 항목 | C2: 편성 금액 [천원] | F2: 변경 [천원] | H2: 변동폭 [천원] | I2: 사용률 | J2: 예측 사용률 | L2: 예정 사용 내용 (소진예정%)
C3: (25.01.07 기준) | F3: (현시점 26.01.12 기준) | I3: (현시점 26.01.12 기준) | J3: (완료시 26.02.28 기준)
B4: 인건비 | E4: 395131 | F4: ← | G4: =ROUND((예산!G5+예산!G27)/1000,0) -> 395131 | H4: (0) | I4: =(SUMIF('RCMS.260112'!$F$3:$F$1048576, "학생인건비", 'RCMS.260112'!$H$3:$H$1048576)+SUMIF('RCMS.260112'!$F$3:$F$1048576, "인건비",'RCMS.260112'!$H$3:$H$1048576)-예산!$P$5)/(예산!$G$5+예산!$G$27) -> 0.70206411 | J4: =SUM(예산!$G$5)/예산!$G$5 -> 1 | K4: Y | L4: 인건비 월별 순차지급 (7%) + 인센티브 (23%) 3차년도 종료후 일괄 지급
B5: 시설, 장비 | C5: =SUM(E5:E8) -> 1153591 | D5: 융합전공 | E5: 253329 | F5: ← | G5: =ROUND((SUM(예산!G70,예산!G80:G82))/1000,0) -> 253329 | H5: (0) | I5: =(SUMIF('RCMS.260112'!$F$3:$F$1048576, "연구시설·장비비", 'RCMS.260112'!$I$3:$I$1048576)-SUM(예산!G71:G75,예산!G77:G79)) / SUM(예산!G70,예산!G80:G82) -> 1.0001184 | J5: 1 | K5: G | L5: 11월 18일 컴공 GPU 3대 도입 완료 (100%)
D6: 첨융 | E6: 900262 | F6: ← | G6: =ROUND((SUM(예산!G71:G79,예산!G90))/1000,0) -> 900262 | H6: (0) | I6: =(SUMIF('RCMS.260112'!$F$3:$F$1048576, "연구시설·장비비", 'RCMS.260112'!$H$3:$H$1048576)-SUM(예산!$G$70,예산!$G$80:$G$82,예산!$P$27)) / SUM(예산!$G$71:$G$82,예산!$G$90) -> 0.60662231 | J6: 1 | K6: G | L6: 11월 18일 첨융 GPU 3대 + 11월 14일 프로브 스테이션, B1500 도입 완료 (39%)
K7: G | L7: 스위치매트릭스 : 11월 14일 도입 완료 (11%)
K8: Y | L8: ALD : 3.52억 최종계약 완료, 도입 진행 중 (39%)
B9: 연구재료비 | E9: 108040 | F9: ↓ | G9: =ROUND(예산!G98/1000,0) -> 72251 | H9: (Δ: -35,789) 1) | I9: =SUMIF('RCMS.260112'!$F$3:$F$1048576, "연구재료비", 'RCMS.260112'!$I$3:$I$1048576)/SUM(예산!$G$98,예산!$P$51) -> 0.98064281 | J9: =SUM(예산!$G$98,예산!$P$51)/SUM(예산!$G$98,예산!$P$51) -> 1 | K9: G | L9: 재료/공정처리비 지원 (2%)
B10: 연구활동비 | C10: =SUM(E10:E11) -> 1141222 | D10: 장학금 | E10: 636987 | F10: ← | G10: =ROUND(예산!G142/1000,0) -> 636987 | H10: (0) | I10: 0.42 | J10: =636987000/683000000 -> 0.93263104 | K10: Y | L10: 한호철 연구원 자료 반영 (26.01.07) - 예측사용률 반영
D11: 그 외 | E11: 504235 | F11: ↑ | G11: =ROUND(SUM(예산!G155,예산!G161,예산!G187,예산!G198,예산!G203,예산!G212,예산!G218,예산!G224,예산!G233,예산!G264,예산!G239)/1000,0) -> 540024 | H11: (Δ: +35,789) 1) | I11: =(SUMIFS('RCMS.260112'!$I$3:$I$1048576, 'RCMS.260112'!$F$3:$F$1048576, "연구활동비",'RCMS.260112'!$AG$3:$AG$1048576, "<>*장학금*"))/(예산!$G$130-예산!$G$142) -> 0.86537846 | J11: =(예산!$G$130-예산!$G$142+예산!$P$57-예산!I200)/(예산!$G$130-예산!$G$142+예산!$P$57) -> 1 | K11: Y | L11: 공정특강, 소모성 비용 (인쇄비, 수료증 등) (1%) 4차년도 GPU, EDA 용역 계약 (7%) 공정처리비 지원, 칩제작 지원 (6%)
B12: Total | E12: =SUM(E4:E11)+155600 -> 2953584 | F12: ← | G12: =ROUND(예산!G3/1000,0)+155600 -> 2953584 | H12: (0) | I12: =SUM(I4*G4,I5*G5,I6*G6,I9*G9,I10*G10,I11*G11,155600)/C18 -> 0.65494775 | J12: =G12/C18 -> 0.94909512 | L12: 간접비 포함 (전체사업비의 5%)
B13: 이월예정액 | E13: =3112000-E12 -> 158416 | G13: =3112000-G12 -> 158416 | H13: (0) | J13: =G13/C18 -> 0.050904884
B18: 총사업비 | C18: 3112000 | H18: 실제사용금액 | I18: =SUM(#REF!) -> #REF! | L18: =( SUMIF(#REF!, "연구시설·장비비",#REF!)-SUM(예산!$G$71:$G$79,예산!$P$27)+SUM(예산!$G$75,예산!$G$76)) -> #REF!
H19: 잔여금액 | I19: =예산!C3+예산!P3-'3차년도 전체요약'!I18 -> #REF! | L19: =SUMIFS(#REF!,#REF!, "연구활동비",#REF!, "*장학금*")/예산!$G$142 -> #REF!
L20: =SUM(I4*G4,I5*G5,I6*G6,I9*G9,I10*G10,I11*G11,155600) -> 2038197.4
O21: ↑
O22: ← | Q22: (Δ: +16,488)
O23: ←
O26: ←
O27: ←
O28: ↑ | P28: ↓
O29: ↓

Sheet RCMS기준사용현황
B1: 3차년도 예산 집행 현황
B2: 항목 | C2: 본예산 편성 금액 [천원] | F2: 사용률 | G2: 예측 사용률 | H2: 이월금 편성 금액 [천원] | I2: 사용률 | J2: 예측 사용률 | M2: 예정 사용 내용 (소진예정%)
F3: (25.11.30 RCMS 기준) | G3: (3차년도 완료시 26.02.28 기준) | I3: (25.11.30 RCMS 기준) | J3: (3차년도 완료시 26.02.28 기준)
B4: 인건비 | E4: =예산!$G5 -> 216130857 | F4: 0.351 | G4: 1 | H4: 4028892 | I4: 1 | J4: =SUM(예산!$G$5)/예산!$G$5 -> 1 | L4: G | M4: 월별 순차지금 (36%) 인센티브 (23%) 3차년도 종료후 일괄 지급
B5: 시설, 장비 | E5: 1302507390 | F5: 0.079 | G5: 0.979 | H5: 282398210 | I5: 0.66 | J5: =(예산!$G$83+예산!$G$90+예산!$P$27)/(예산!$G$67+예산!$P$27) -> 1 | L5: G | M5: ALD 제외 모든장비 도입완료, 검수 및 지출 절차 진행중 (57%) ALD 12월 말 도입예정 (22.6%) 컴공 세미나실 지원금 미사용 (1.8%)
B6: 연구재료비 | E6: 108039500 | F6: 0.622 | G6: 0.995 | H6: 1144000 | I6: 0 | J6: =SUM(예산!$G$98,예산!$P$51)/SUM(예산!$G$98,예산!$P$51) -> 1 | L6: Y | M6: 첨융 교육용 칩 제작 공정처리비 (32.5%) 재료/공정처리비 지원 (6%)
B7: 연구활동비 | E7: 1144554352 | F7: 0.717 | G7: 0.978 | H7: 198119549 | I7: 0.398 | J7: =(예산!$G$130-예산!$G$142+예산!$P$57-예산!G197)/(예산!$G$130-예산!$G$142+예산!$P$57) -> 1 | L7: G | M7: one-day 공정특강, 소모성 비용 (인쇄비, 수료증 등) (5.9%)
B8: 학생인건비 | E8: =186800000 -> 186800000 | F8: 1 | G8: =SUM(예산!$G$27)/예산!$G$27 -> 1 | H8: 0 | I8: - | J8: - | L8: G | M8: 풀링계좌 인건비 이체 완료, 변동사항 없음
B9: 간접비 | E9: 155600000 | F9: 1 | G9: =예산!$C$267/예산!$C$267 -> 1 | H9: 0 | I9: - | J9: - | L9: G | M9: 간접비 지출 완료
B10: Total | E10: =SUM(E4:E9) -> 3113632099 | F10: 0.453 | G10: =1-G12/E10 -> 0.98295462 | H10: =SUM(H4:H7) -> 485690651 | I10: 0.555 | J10: 1
M11: 미사용 예정 금액: 4차년도 협약이전 인건비 활용 등 (1.4%)
B12: 이월예정액 | G12: =E4*(1-G4)+E5*(1-G5)+E6*(1-G6)+E7*(1-G7)+E8*(1-G8)+E9*(1-G9) -> 53073048
B16: 총사업비 | C16: 2956400 | F16: =SUMIFS(#REF!,#REF!, "연구활동비",#REF!, "*장학금*") -> #REF! | I16: =예산!G142 -> 636987000
F17: =SUMIFS(#REF!,#REF!, "연구활동비",#REF!, "<>*장학금*") -> #REF! | I17: =(예산!G130-예산!G142) -> 540023574
F18: =SUMIF(#REF!, "연구재료비",#REF!) -> #REF!
O19: ↑
O20: ← | Q20: (Δ: +16,488)
O21: ←
O24: ←
O25: ←
O26: ↑ | P26: ↓
O27: ↓

Sheet 예산
A1: 3차년도 예산 | J1: 2차년도 이월금
B2: 직접비+간접비 | C2: =3050000000 + 62000000 -> 3112000000
A3: 1 | B3: 직접비 | C3: =C2*0.95 -> 2956400000 | F3: 현재까지 총액 | G3: =SUM(G5,G27,G67,G98,G130) -> 2797983630 | H3: =C3-G3 -> 158416370 | J3: 1 | K3: 직접비 | L3: 485690651 | O3: 현재까지 총액 | P3: =SUM(P5,P16,P27,P51,P57) -> 485690651 | Q3: =L3 -> 485690651 | R3: =Q3-P3 -> 0 | S3: =P3+G3+H3 -> 3442090651
Q4: 기준
A5: 1) | B5: 인건비 | G5: =SUM(G15,G20) -> 216130857 | J5: 1) | K5: 인건비 | P5: =P14 -> 4028892 | Q5: 4028892 | R5: =Q5-P5 -> 0
B6: 구분 | C6: 성명 | D6: 직위 | E6: 월 급여 | F6: 참여기간(개월) | G6: 금액(원) | H6: 전미자 선생님 7월 월급 기관부담금포함 1,047,560원 | K6: 구분 | L6: 성명 | M6: 직위 | N6: 월 급여 | O6: 참여기간(개월) | P6: 금액(원)
B7: 행정전담인력 | C7: 전미자 (25.5 - 25.7 중순) | D7: 행정원 | E7: 1815760 | F7: 2 | G7: =(E7*F7)+1192128+1047560 -> 5871208 | H7: 이월금에서 모자란 금액 1,192,128만큼 본예산에서 집행 | K7: 행정전담인력 | L7: 전미자 | M7: 행정원 | N7: 1815760 | O7: 2 | P7: =(N7*O7)-1223848+31720 -> 2439392 | Q7: 모자란 금액 1,192,128만큼 본예산에서 집행
C8: 강훈경 (25.4 - 25.6) | D8: 행정원 | E8: 1589500 | F8: 3 | G8: =E8*F8 -> 4768500 | L8: 강훈경 | M8: 행정원 | N8: 1589500 | O8: 1 | P8: =N8*O8 -> 1589500 | Q8: =-1223848+31720 -> -1192128
C9: 강훈경 (25.7 - 25.12) | D9: 행정원 | E9: =2450884 -> 2450884 | F9: 6 | G9: =E9*F9 -> 14705304
C10: 강훈경 (26.1 - 26.2) | D10: 행정원 | E10: =3267829 -> 3267829 | F10: 2 | G10: =E10*F10 -> 6535658
C11: 한호철 | D11: 행정원 | E11: 4668777 | F11: 8 | G11: =E11*F11 -> 37350216 | L11: 소계 | P11: =SUM(P7:P8) -> 4028892
C12: 권상미 | D12: 행정원 | E12: 4668777 | F12: 7 | G12: =E12*F12 -> 32681439
C13: 양수림 | D13: 행정원 | E13: 3476422 | F13: 6 | G13: =E13*F13 -> 20858532
C14: 소계 | G14: =SUM(G7:G13) -> 122770857 | K14: 합계 | P14: =SUM(P11) -> 4028892
B15: 합계 | G15: =SUM(G14) -> 122770857
J16: 2) | K16: 학생 인건비 | L16: =COUNT(#REF!,#REF!,#REF!) -> 0 | P16: 0
B17: 인센티브 | C17: (정부출연금의 3%이내)
B18: 구분 | C18: 산출내역 | G18: 금액(원)
B19: 참여교수 및 직원 | G19: =C2*0.03 -> 93360000
B20: 합계 | G20: =G19 -> 93360000
B22: 초과시수수당
B23: 구분 | C23: 산출내역 | G23: 금액(원)
B24: 참여교수 및 직원
B25: 합계
A27: 2) | B27: 학생 인건비 | C27: =COUNT(G29:G54,#REF!,G56:G63) -> 34 | G27: =SUM(G65) -> 179000000 | J27: 3) | K27: 연구시설장비비 | P27: =P32 -> 282398210 | Q27: 282398210 | R27: =Q27-P27 -> 0
B28: 구분 | C28: 성명 | D28: 직위 | E28: 월 급여 | F28: 참여기간(개월) | G28: 금액(원) | K28: 연구장비 구입 및 임차비
B29: 교육 TA | C29: 김성주 | D29: 멘토 TA | E29: 900000 | F29: 8 | G29: =E29*F29 -> 7200000 | H29: 1학기, 2학기만. 인건비 확보 위해 10 --> 90 증액 | K29: 품명 | L29: 용도 | M29: 단위 | N29: 수량 | O29: 단가(원) | P29: 현금(원)
C30: 이찬 | D30: 장비 TA | E30: 900000 | F30: 12 | G30: =E30*F30 -> 10800000 | K30: 첨단융합학부 | L30: GPU | N30: 1 | O30: 84348000 | P30: 95987810 | Q30: 모자란 금액 (84,348,000 - 95,987,810)만큼 본예산 | R30: =84348000*1-P30 -> -11639810
C31: 윤태현(이철호 교수님) | D31: 장비 TA | E31: 900000 | F31: 12 | G31: =E31*F31 -> 10800000 | L31: Pulse Module | N31: 3 | O31: 62136800 | P31: =N31*O31 -> 186410400 | Q31: 납품 지연 --> 심의, 계약은 완료되었으므로 이월 가능
C32: 김주현 | D32: 장비 TA | E32: 900000 | F32: 3 | G32: =E32*F32 -> 2700000 | H32: 3-5월 EDA 용역 공백기간 | K32: 합계 | P32: =SUM(P30:P31) -> 282398210
C33: 조형준 | D33: 장비 TA | E33: 900000 | F33: 3 | G33: =E33*F33 -> 2700000
C34: 류명현(컴공) | D34: GPU 관리 TA | E34: 900000 | F34: 12 | G34: =E34*F34 -> 10800000 | K34: 교육시설 설비 구축 및 개선
C35: 김지원(컴공) | D35: GPU 관리 TA | E35: 900000 | F35: 12 | G35: =E35*F35 -> 10800000 | K35: 구분 | L35: 품명 | M35: 규격 | N35: 수량 | O35: 단가(원) | P35: 현금(원)
C36: 황동호 | D36: 경진대회 TA | E36: 1300000 | F36: 1 | G36: =E36*F36 -> 1300000 | H36: 3차년도 교내경진대회 1달로 축소 (6월)
C37: 노혜리 | D37: 경진대회 TA | E37: 1300000 | F37: 1 | G37: =E37*F37 -> 1300000 | P37: =O37*N37 -> 0
C38: 정제승 | D38: 첨융 칩 설계 TA | E38: 900000 | F38: 6 | G38: =E38*F38 -> 5400000 | H38: 3 ~ 8월, 정규원 교수님 연구실 신입생 2명 | P38: =O38*N38 -> 0
C39: 김민선 | D39: 첨융 칩 설계 TA | E39: 900000 | F39: 6 | G39: =E39*F39 -> 5400000 | P39: =O39*N39 -> 0
C40: 고용예정 | D40: 특강 보조 TA | E40: 900000 | F40: 0 | G40: =E40*F40 -> 0
C41: 고용예정 | D41: 특강 보조 TA | E41: 900000 | F41: 0 | G41: =E41*F41 -> 0
C42: 고용예정 | D42: 특강 보조 TA | E42: 900000 | F42: 0 | G42: =E42*F42 -> 0 | H42: 9 ~ 12월 (추후 선발) | K42: 합계
...

Sheet 소진일정
A1: 3차년도 예산 집행예상내역 | O1: 일자별 누적 기록 | AD1: 3월 | AE1: 4월 | AF1: 5월 | AG1: 6월 | AH1: 7월 | AI1: 8월 | AJ1: 9월 | AK1: 10월 | AL1: 11월 | AM1: 12월 | AN1: 1월 | AO1: 2월 | AP1: 총계(=2,956,400,000 원) | AQ1: 예상이월금
A2: =예산!C3 -> 2956400000 | J2: = 예상 이월금 | O2: 날짜 | P2: 인건비 | R2: 학생인건비 | T2: 연구시설장비비 | V2: 연구재료비 | X2: 연구활동비 | Z2: 총계 | AD2: =SUMIF($G4:$G187, AD1, $H4:$H187) -> 14600000 | AE2: =SUMIF($G4:$G187, AE1, $H4:$H187) -> 17381628 | AF2: =SUMIF($G4:$G187, AF1, $H4:$H187) -> 75237443 | AG2: =SUMIF($G4:$G187, AG1, $H4:$H187) -> 31124560 | AH2: =SUMIF($G4:$G187, AH1, $H4:$H187) -> 429067730 | AI2: =SUMIF($G4:$G187, AI1, $H4:$H187) -> 36033827 | AJ2: =SUMIF($G4:$G187, AJ1, $H4:$H187) -> 258031129 | AK2: =SUMIF($G4:$G187, AK1, $H4:$H187) -> 231273623 | ... AO2: =SUMIF($G4:$G187, AO1, $H4:$H187) -> 436940689 | AP2: =SUM(AD2:AO2) -> 2744245126 | AQ2: =$A$2-$AP$2 -> 212154874
A3: 항목 | B3: 세목 | C3: 3차년도 예산 | D3: 세부집행 계획 | G3: 집행예상 월 | H3: 집행액 예정 금액 | I3: 집행일 | J3: 집행잔액 | K3: 집행률 | O3: 현황 | P3: =H18 -> 240639599 | Q3: =K18 -> 1.1133977 | R3: =H31 -> 186800000 | S3: =K31 -> 1.0435754 | T3: =H48 -> 1154900740 | U3: =K48 -> 1.0011356 | V3: =H68 -> 43226509 | W3: =K68 -> 0.5982787 | X3: =H197 -> 1141074289 | Y3: =K197 -> 0.96946817 | Z3: =H198 -> 2766641137 | AA3: =K198 -> 0.98879819 | AD3: =AD2/$A$2 -> 0.0049384386 | AE3: =AE2/$A$2+AD3 -> 0.010817761 | AF3: =AF2/$A$2+AE3 -> 0.036266767 | AG3: =AG2/$A$2+AF3 -> 0.046794626 | AH3: =AH2/$A$2+AG3 -> 0.19192645 | AI3: =AI2/$A$2+AH3 -> 0.20411487 | AJ3: =AJ2/$A$2+AI3 -> 0.29139369 | AK3: =AK2/$A$2+AJ3 -> 0.36962182 | AL3: =AL2/$A$2+AK3 -> 0.59505955 | ... AO3: =AO2/$A$2+AN3 -> 0.92823878 | AP3: =AP2/$A$2 -> 0.92823878 | AQ3: =AQ2/$A$2 -> 0.071761221
A4: 인건비 | B4: 직원인건비 | C4: =예산!G15 -> 122770857 | D4: 전미자 | E4: =예산!G7 -> 5871208 | G4: 4월 | H4: =1192128+예산!E8 -> 2781628 | I4: 45776 | O4: 45788 | P4: 2781628 | Q4: 0.015020954 | R4: 14600000 | S4: 0.071921182 | T4: 0 | U4: 0 | V4: 0 | W4: 0 | X4: 5500000 | Y4: 0.0044688636 | Z4: 22881628 | AA4: 0.0077396929
D5: 강훈경 | E5: =예산!G8 -> 4768500 | G5: 5월 | H5: =예산!E7+예산!E8 -> 3405260 | AD5: *장학금부분
D6: 강훈경 | E6: =예산!G9 -> 14705304 | G6: 6월 | H6: =SUM(예산!$E$7:$E$8) -> 3405260 | AD6: 3월 | AE6: 4월 | AF6: 5월 | AG6: 6월 | AH6: 7월 | AI6: 8월 | AJ6: 9월 | AK6: 10월 | AL6: 11월 | AM6: 12월 | AN6: 1월 | AO6: 2월 | AP6: 총계(=2,956,400,000 원)
D7: 한호철 | E7: =예산!G11 -> 37350216 | G7: 7월 | H7: =SUM(예산!$E$9:$E$11) -> 10387490 | AD7: =SUMIF($G$69:$G$113, AD$6, $H$69:$H$113) -> 0 | AE7: =SUMIF($G$69:$G$113, AE$6, $H$69:$H$113) -> 0 | AF7: =SUMIF($G$69:$G$113, AF$6, $H$69:$H$113) -> 6500000 | AG7: =SUMIF($G$69:$G$113, AG$6, $H$69:$H$113) -> 1000000 | AH7: =SUMIF($G$69:$G$113, AH$6, $H$69:$H$113) -> 207800000 | AI7: =SUMIF($G$69:$G$113, AI$6, $H$69:$H$113) -> 0 | AJ7: =SUMIF($G$69:$G$113, AJ$6, $H$69:$H$113) -> 2000000 | AK7: =SUMIF($G$69:$G$113, AK$6, $H$69:$H$113) -> 113838000 | ... AO7: =SUMIF($G$69:$G$113, AO$6, $H$69:$H$113) -> 310000000 | AP7: =SUM(AD7:AO7) -> 671838000
D8: 권상미 | E8: =예산!G12 -> 32681439 | G8: 8월 | H8: =SUM(예산!$E$9:$E$12)+1047560 -> 16103827 | AD8: =SUMIF($G$69:$G$113, AD$6, $H$69:$H$113) -> 0 | AE8: =SUMIF($G$69:$G$113, AE$6, $H$69:$H$113)+AD8 -> 0 | AF8: =SUMIF($G$69:$G$113, AF$6, $H$69:$H$113)+AE8 -> 6500000 | AG8: =SUMIF($G$69:$G$113, AG$6, $H$69:$H$113)+AF8 -> 7500000 | AH8: =SUMIF($G$69:$G$113, AH$6, $H$69:$H$113)+AG8 -> 215300000 | AI8: =SUMIF($G$69:$G$113, AI$6, $H$69:$H$113)+AH8 -> 215300000 | AJ8: =SUMIF($G$69:$G$113, AJ$6, $H$69:$H$113)+AI8 -> 217300000 | AK8: =SUMIF($G$69:$G$113, AK$6, $H$69:$H$113)+AJ8 -> 331138000 | AL8: =SUMIF($G$69:$G$113, AL$6, $H$69:$H$113)+AK8 -> 349838000 | ... AO8: =SUMIF($G$69:$G$113, AO$6, $H$69:$H$113)+AN8 -> 671838000
D9: 양수림 | E9: =예산!G13 -> 20858532 | G9: 9월 | H9: =SUM(예산!$E$9:$E$13) -> 18532689 | AD9: =AD7/$E$114 -> 0 | AE9: =AE7/$E$114+AD9 -> 0 | AF9: =AF7/$E$114+AE9 -> 0.01020429 | AG9: =AG7/$E$114+AF9 -> 0.011774181 | AH9: =AH7/$E$114+AG9 -> 0.33799748 | AI9: =AI7/$E$114+AH9 -> 0.33799748 | AJ9: =AJ7/$E$114+AI9 -> 0.34113726 | AK9: =AK7/$E$114+AJ9 -> 0.51985048 | AL9: =AL7/$E$114+AK9 -> 0.54920744 | ... AO9: =AO7/$E$114+AN9 -> 1.0547123 | AP9: =AP7/$A$2 -> 0.22724868
G10: 10월 | H10: =SUM(예산!$E$9:$E$13) -> 18532689
G11: 11월 | H11: =SUM(예산!$E$9:$E$13) -> 18532689
G12: 12월 | H12: =SUM(예산!$E$9:$E$13) -> 18532689
G13: 1월 | H13: =SUM(예산!$E$9:$E$13) -> 18532689
G14: 2월 | H14: =SUM(예산!$E$9:$E$13) -> 18532689
B15: 소계 | E15: =SUM(E4:E14) -> 116235199 | H15: =SUM(H4:H14) -> 147279599
B16: 인센티브 | C16: =예산!G20 -> 93360000 | G16: 2월 | H16: =C16 -> 93360000
B17: 소계 | E17: =$C16 -> 93360000 | H17: =SUM(H16) -> 93360000
A18: 소계 (인건비) | C18: =C4+C16 -> 216130857 | E18: =C18 -> 216130857 | H18: =H15+H17 -> 240639599 | K18: =H18/C18 -> 1.1133977
A19: 학생인건비 | B19: 학생인건비 | C19: =예산!G27 -> 179000000 | G19: 3월 | H19: =1300000*5+900000*9 -> 14600000 | I19: 45778
G20: 4월 | H20: =1300000*5+900000*9 -> 14600000
G21: 5월 | H21: =1300000*5+900000*9 -> 14600000
G22: 6월 | H22: =1300000*5+900000*7+1300000*2 -> 15400000
G23: 7월 | H23: =1300000*5+900000*6 -> 11900000
G24: 8월 | H24: =1300000*5+900000*6 -> 11900000
G25: 9월 | H25: =1300000*5+900000*16 -> 20900000
G26: 10월 | H26: =1300000*5+900000*16 -> 20900000
G27: 11월 | H27: =1300000*5+900000*16 -> 20900000
G28: 12월 | H28: =1300000*5+900000*16 -> 20900000
G29: 1월 | H29: =1300000*5+900000*4 -> 10100000
G30: 2월 | H30: =1300000*5+900000*4 -> 10100000
A31: 소계 (학생인건비) | C31: =C19 -> 179000000 | E31: =C31 -> 179000000 | H31: =SUM(H19:H30) -> 186800000 | K31: =H31/C31 -> 1.0435754
A32: 연구시설장비비 | B32: 연구시설 장비구입 및 임차비 | C32: GPU | D32: 융합전공 | E32: =예산!G70 -> 253044000 | G32: 11월 | H32: =E32 -> 253044000
D33: 첨융 | E33: =+예산!G71 -> 157056190 | G33: 11월 | H33: =E33 -> 157056190
C34: Hall measurement | E34: =예산!G72 -> 29920000 | G34: 7월 | H34: =E34 -> 29920000
C35: probe station | E35: =예산!G73 -> 95705550 | G35: 11월 | H35: =E35 -> 95705550
C36: B1500 | E36: =예산!G74 -> 96997000 | G36: 11월 | H36: =E36 -> 96997000 | J36: 9월까지의 장비 | K36: =SUM(H32:H36,H40:H41)/A2 -> 0.2241756
C37: ALD | E37: 352000000 | G37: 1월 | H37: =E37 -> 352000000
C38: 스위치매트릭스 | E38: 95000000 | G38: 1월 | H38: =E38 -> 95000000 | J38: 하반기 장비 | K38: =SUM(H37:H39)/A2 -> 0.16574144
C39: 엘립소미터 | E39: 42998000 | G39: 10월 | H39: =E39 -> 42998000
C40: 광학현미경 | E40: 22000000 | G40: 9월 | H40: =E40 -> 22000000
...

Sheet 재정투자 계획 총괄표, 대응자금
A1: < 재정투자 계획 총괄표> (단위 : 백만원, %)
A2: 구 분 | B2: 정부출연금(A) | H2: 평균 | I2: 민간투자지원*
H3: 비율 | M3: 교육운영비 동영상 인센티브 1400 반공연 공정실습 1200 기업협업교과목 1200
B4: 1차년도 | C4: 이월금 | D4: 2차년도 | E4: 이월금 | F4: 3차년도 | G4: 4차년도 | H4: (%) | I4: 현금 | J4: 현물 | K4: 소계
B5: (‘23.3～’24.2) | D5: (‘24.3～’25.2) | F5: (‘25.3～’26.2) | G5: (‘26.3～’27.2) | I5: (a) | J5: (b) | K5: (a+b)
A6: 직접비 | B6: 4142 | C6: 1169.9 | D6: 3808.79 | E6: 485.69 | F6: =예산!C3/1000000 -> 2956.4 | G6: =F6 -> 2956.4 | H6: =(SUM(B6,D6,F6,G6) / $C$17)*100 -> 97.108327 | J6: - | W6: 2956.4
A7: 인건비 | B7: 223.5 | C7: 44.9 | D7: 209.73 | E7: 4.03 | F7: =예산!G5/1000000 -> 216.13086 | G7: =F7 -> 216.13086 | H7: =(SUM(B7,D7,F7,G7) / $C$17)*100 -> 6.0623873 | J7: - | W7: 214.5
A8: 학생인건비 | B8: 210.8 | C8: 0 | D8: 248.2 | E8: 0 | F8: =예산!G27/1000000 -> 179 | G8: =F8 -> 179 | H8: =(SUM(B8,D8,F8,G8) / $C$17)*100 -> 5.7227243 | J8: - | W8: 186.8
A9: 연구시설·장비비 | B9: 2134.71 | C9: 329 | D9: 2611.8 | E9: 282.4 | F9: =예산!G67/1000000 -> 1153.5907 | G9: =F9 -> 1153.5907 | H9: =(SUM(B9,D9,F9,G9) / $C$17)*100 -> 49.407995 | J9: - | W9: 1302.51
A10: 연구재료비 | B10: 168.86 | C10: 21.5 | D10: 19.19 | E10: 1.14 | F10: =예산!G98/1000000 -> 72.251459 | G10: =F10 -> 72.251459 | H10: =(SUM(B10,D10,F10,G10) / $C$17)*100 -> 2.3293864 | J10: - | O10: 4.91 | W10: 108.04
A11: 연구활동비 | B11: 1404.13 | C11: 774.5 | D11: 719.87 | E11: 198.12 | F11: =예산!G130/1000000 -> 1177.0106 | G11: =F11 -> 1177.0106 | H11: =(SUM(B11,D11,F11,G11) / $C$17)*100 -> 31.366561 | J11: - | O11: 6.48 | W11: 1144.55
A12: 소계 | B12: 4142 | C12: 1169.9 | D12: =SUM(D7:D11) -> 3808.79 | E12: =SUM(E7:E11) -> 485.69 | F12: =SUM(F7:F11) -> 2797.9836 | G12: =SUM(G7:G11) -> 2797.9836 | H12: =SUM(H7:H11) -> 94.889054 | J12: - | O12: 49.97 | W12: 2956.4
A13: 간접비 | B13: 218 | C13: 0 | D13: 200.46 | E13: 0 | F13: =예산!C267/1000000 -> 155.6 | G13: =F13 -> 155.6 | H13: =(SUM(B13,D13,F13,G13) / $C$17)*100 -> 5.1109462 | J13: - | O13: 3.06 | W13: 155.6
A14: 소계 | B14: 218 | C14: 0 | D14: 200.46 | E14: 0 | F14: =SUM(F13) -> 155.6 | G14: =F14 -> 155.6 | H14: =SUM(H13) -> 5.1109462 | J14: - | O14: 30.58 | W14: 155.6
A15: 합 계 | B15: 4360 | C15: 1169.9 | D15: =SUM(D12,D14) -> 4009.25 | E15: =SUM(E12,E14) -> 485.69 | F15: =SUM(F12,F14) -> 2953.5836 | G15: =SUM(G12,G14) -> 2953.5836 | H15: =SUM(H12,H14) -> 100 | J15: - | W15: 3112
A16: *이월금 포함
A17: 합계 총합 | C17: =SUM(B15,D15,F15,G15) -> 14276.417
A20: 구분 | C20: 삼성전자 | D20: sk하이닉스
A22: 인센티브 | C22: 4000000 | D22: 7000000 | E22: =SUM(C22:D22) -> 11000000 | G22: =SUM(C22:D28) -> 104005000 | H22: =SUM(G22,E29) -> 112630000
A23: 연구시설장비비 | C23: 3800000 | E23: =SUM(C23:D23) -> 3800000
A24: 연구활동비 | B24: 교육 운영비 | C24: 39000000 | E24: =SUM(C24:D24) -> 39000000 | F24: =SUM(E24:E28) -> 89205000
E25: =SUM(C25:D25) -> 0
B26: 출장비 | C26: 5000000 | D26: 7875000 | E26: =SUM(C26:D26) -> 12875000
B27: 행사운영비 | C27: 1000000 | D27: =17000000+13330000 -> 30330000 | E27: =SUM(C27:D27) -> 31330000
B28: 회의비 | C28: 6000000 | E28: =SUM(C28:D28) -> 6000000
A29: 간접비 | C29: 3000000 | D29: 5625000 | E29: =SUM(C29:D29) -> 8625000
J30: =37500000-24171200 -> 13328800
A31: 합계 | C31: =SUM(C22:C29) -> 61800000 | D31: =SUM(D22:D29) -> 50830000
A32: 5000+1180(이월금) | C32: 61800000 | D32: =37500000+13330000 -> 50830000 | E32: 3750+1333(이월금)
C33: =C32-C31 -> 0 | D33: =D32-D31 -> 0
A36: 행사운영비: 엔지니어링하우스에서 간담회 할때 대관료 대응자금

Sheet 3차년도 사업비 편성 총괄표
A1: < 3차년도 사업비 편성 총괄표> (단위 : 백만원, %)
A2: 구 분 | C2: 정부출연금 | D2: 비율 | E2: 이월금 | F2: 민간투자지원*
D3: (%) | F3: 현금(a) | G3: 현물(b) | H3: 소계(a+b)
A4: 인건비 | B4: 직원 인건비 | C4: =예산!G15/1000000 -> 122.77086 | D4: =(C4/$C$27)*100 -> 4.1566745 | E4: 4.03 | F4: 0 | H4: 0 | N4: 121.14
B5: 인센티브 | C5: =예산!G20/1000000 -> 93.36 | D5: =(C5/$C$27)*100 -> 3.1609059 | E5: 0 | F5: 10 | H5: 10 | N5: 93.36
A6: 소계 | C6: =SUM(C4,C5) -> 216.13086 | D6: =SUM(D4:D5) -> 7.3175804 | E6: =SUM(E4:E5) -> 4.03 | F6: =SUM(F4:F5) -> 10 | H6: =SUM(H4:H5) -> 10 | N6: 214.5
A7: 학생 인건비 | B7: 학생인건비 | C7: =예산!G65/1000000 -> 179 | D7: =(C7/$C$27)*100 -> 6.0604345 | E7: 0 | F7: 0 | H7: 0 | N7: 186.8
A8: 소계 | C8: =SUM(C7) -> 179 | D8: =SUM(D7) -> 6.0604345 | E8: 0 | F8: 0 | H8: 0 | N8: 186.8
A9: 연구시설 장비비 | B9: 연구장비 구입 및 임차비 | C9: =예산!G83/1000000 -> 1151.5907 | D9: =(C9/$C$27)*100 -> 38.98961 | E9: 282.4 | F9: 0 | H9: 0 | N9: 1272.51
B10: 교육시설 설비 구축 및 개선 | C10: =예산!G91/1000000 -> 2 | D10: =(C10/$C$27)*100 -> 0.067714351 | E10: 0 | F10: 3 | H10: 3 | N10: 30
A11: 연구 재료비 | B11: 재료비 | C11: =예산!G127/1000000 -> 72.251459 | D11: =(C11/$C$27)*100 -> 2.4462303 | E11: 1.14 | F11: 0 | H11: 0 | N11: 108.04
A12: 연구 활동비 | B12: 장학금 | C12: =예산!G142/1000000 -> 636.987 | D12: =(C12/$C$27)*100 -> 21.566581 | E12: 0 | F12: 0 | H12: 0 | N12: 678.99
B13: 출장비 | C13: =예산!G155/1000000 -> 2.984168 | D13: =(C13/$C$27)*100 -> 0.1010355 | E13: 0 | F13: 12.88 | H13: 12.88 | N13: 3.12
B14: 회의비 | C14: =예산!G161/1000000 -> 1.1741 | D14: =(C14/$C$27)*100 -> 0.03975171 | E14: 0 | F14: 5 | H14: 5 | N14: 0.58
B15: 연구인력 지원비 | C15: =예산!G187/1000000 -> 76.035185 | D15: =(C15/$C$27)*100 -> 2.5743366 | E15: 0 | F15: 0 | H15: 0 | N15: 77.07
B16: 연구활동 유지비 | C16: =예산!G239/1000000 -> 39.6 | D16: =(C16/$C$27)*100 -> 1.3407442 | E16: 39.6 | F16: 0 | H16: 0 | N16: 0
B17: 연구실 운영비 | C17: =예산!G198/1000000 -> 1.5241 | D17: =(C17/$C$27)*100 -> 0.051601722 | E17: 0.61 | F17: 0 | H17: 0 | N17: 1.52
B18: 문헌구입비 | C18: =예산!G203/1000000 -> 0.15 | D18: =(C18/$C$27)*100 -> 0.0050785764 | E18: 0 | F18: 0 | H18: 0 | N18: 0.15
B19: 인쇄비 | C19: =예산!G212/1000000 -> 14.739 | D19: =(C19/$C$27)*100 -> 0.49902091 | E19: 0.15 | F19: 0 | H19: 0 | N19: 11.66
B20: 운영경비-공공요금 | C20: =예산!G218/1000000 -> 2.068 | D20: =(C20/$C$27)*100 -> 0.070016639 | E20: 0 | F20: 0 | H20: 0 | N20: 2.07
B21: 소프트웨어 활용비 | C21: =예산!G233/1000000 -> 350.63618 | D21: =(C21/$C$27)*100 -> 11.871551 | E21: 157.76 | F21: 0 | H21: 0 | N21: 350.64
B22: 행사운영비 | C22: =예산!G224/1000000 -> 1.1948 | D22: =(C22/$C$27)*100 -> 0.040452554 | E22: 0 | F22: 18 | H22: 18 | N22: 4.62
B23: 교육운영비 | C23: =예산!G264/1000000 -> 49.918041 | D23: =(C23/$C$27)*100 -> 1.6900839 | E23: 0 | F23: 38 | H23: 38 | N23: 14.13
A24: 소계 | C24: =SUM(C9:C23) -> 2402.8528 | D24: =SUM(D9:D23) -> 81.353809 | E24: =SUM(E9:E23) -> 481.66 | F24: =SUM(F9:F23) -> 76.88 | H24: =SUM(H9:H23) -> 76.88 | N24: 2555.1
A25: 간접비 | C25: =예산!C267/1000000 -> 155.6 | D25: =(C25/$C$27)*100 -> 5.2681765 | E25: 0 | F25: 8.62 | H25: 8.62 | N25: 155.6
A26: 소계 | C26: =SUM(C25) -> 155.6 | D26: =SUM(D25) -> 5.2681765 | E26: 0 | F26: 8.62 | H26: 8.62 | N26: 155.6
A27: 합 계 | C27: =SUM(C6,C8,C24,C26) -> 2953.5836 | D27: =SUM(D6,D8,D24,D26) -> 100 | E27: =SUM(E24,E26,E8,E6) -> 485.69 | F27: =SUM(F26,F24,F6,F8) -> 95.5 | H27: =SUM(H26,H24,H6,H8) -> 95.5 | N27: 3112
A28: *이월금 포함
A30: 구분 | C30: 삼성전자* | D30: SK 하이닉스
A31: 인센티브 | C31: 5000000 | D31: 7000000 | E31: =SUM(C31:D31) -> 12000000 | G31: =SUM(E31:E37) -> 88875000
A32: 연구시설장비비 | C32: 2000000 | D32: 0 | E32: =SUM(C32:D33) -> 2000000
A34: 연구활동비 | B34: 교육운영비 | C34: 40000000 | D34: 0 | E34: =SUM(C34:D34) -> 40000000 | F34: =SUM(E34:E37) -> 74875000
B35: 출장비 | C35: 4500000 | D35: 7875000 | E35: =SUM(C35:D35) -> 12375000
B36: 행사운영비 | C36: 1000000 | D36: 17000000 | E36: =SUM(C36:D36) -> 18000000
B37: 회의비 | C37: 4500000 | D37: 0 | E37: =SUM(C37:D37) -> 4500000
A38: 간접비 | C38: 3000000 | D38: 5625000 | E38: =SUM(C38:D38) -> 8625000

Sheet 3차년도 사업비 소진현황 (지출)
A1: 3차년도 예산 집행 확실 내역 | O1: 일자별 누적 기록 | AC1: 월별 소진 현황 | AD1: 3월 | AE1: 4월 | AF1: 5월 | AG1: 6월 | AH1: 7월 | AI1: 8월 | AJ1: 9월 | AK1: 10월 | AL1: 11월 | AM1: 12월 | AN1: 1월 | AO1: 2월 | AP1: 총계(=2,956,400,000 원) | AQ1: 예상이월금
A2: =예산!C3 -> 2956400000 | J2: = 예상 이월금 | O2: 날짜 | P2: 인건비 | R2: 학생인건비 | T2: 연구시설장비비 | V2: 연구재료비 | X2: 연구활동비 | Z2: 총계 | AD2: =SUMIF($G6:$G178, AD1, $H6:$H178) -> 0 | AE2: =SUMIF($G6:$G178, AE1, $H6:$H178) -> 6810520 | AF2: =SUMIF($G6:$G178, AF1, $H6:$H178) -> 209059160 | AG2: =SUMIF($G6:$G178, AG1, $H6:$H178) -> 376785260 | AH2: =SUMIF($G6:$G178, AH1, $H6:$H178) -> 270219411 | AI2: =SUMIF($G6:$G178, AI1, $H6:$H178) -> 32954493 | AJ2: =SUMIF($G6:$G178, AJ1, $H6:$H178) -> 299427648 | AK2: =SUMIF($G6:$G178, AK1, $H6:$H178) -> 58817390 | ... AO2: =SUMIF($G6:$G178, AO1, $H6:$H178) -> 0 | AP2: =SUM(AD2:AO2) -> 1405167427 | AQ2: =$A$2-$AP$2 -> 1551232573
A3: 항목 | B3: 세목 | C3: 3차년도 예산 | D3: 세부집행 계획 | G3: 실제 집행내역 | H3: 집행액 (RCMS 기준) | I3: 집행일 | J3: 집행잔액 | K3: 집행률 | O3: 현황 | P3: =H26 -> 128580500 | Q3: =K26 -> 0.59491968 | R3: =H39 -> 186800000 | S3: =K39 -> 1.0435754 | T3: =H56 -> 103213000 | U3: =K56 -> 0.089471072 | V3: =H76 -> 67164759 | W3: =K76 -> 0.92959727 | X3: =H153 -> 0 | Y3: =K153 -> 0 | Z3: =H154 -> 0 | AA3: =K154 -> 0 | AD3: =AD2/$A$2 -> 0 | AE3: =AE2/$A$2 -> 0.0023036531 | AF3: =AF2/$A$2 -> 0.070714098 | AG3: =AG2/$A$2 -> 0.12744732 | AH3: =AH2/$A$2 -> 0.091401506 | AI3: =AI2/$A$2 -> 0.011146832 | AJ3: =AJ2/$A$2 -> 0.10128117 | AK3: =AK2/$A$2 -> 0.019894936 | ... AQ3: =AQ2/$A$2 -> 0.52470321
A4: 인건비 | B4: 직원인건비 | C4: =예산!G15 -> 122770857 | D4: 전미자 | G4: 11월 | H4: 15264848 | I4: 45981 | O4: 45788 | P4: 2781628 | Q4: 0.015020954 | R4: 14600000 | S4: 0.071921182 | T4: 0 | U4: 0 | V4: 0 | W4: 0 | X4: 5500000 | Y4: 0.0044688636 | Z4: 22881628 | AA4: 0.0077396929
D5: 강훈경 | G5: 10월 | H5: 15264848 | I5: 45948 | O5: 45804 | P5: 6186888 | Q5: 0.033409558 | R5: 29200000 | S5: 0.14384236 | T5: 0 | U5: 0 | V5: 0 | W5: 0 | X5: 12540700 | Y5: 0.010181921 | Z5: 47927588 | AA5: 0.016212456
D6: 미정 | G6: 9월 | H6: 15264848 | I6: 45923 | P6: 2.1449876e+08 | Q6: 1 | R6: 179000000 | S6: 1 | T6: 1229517390 | U6: 0.98221729 | V6: 108039500 | W6: 1 | X6: 8829000 | Y6: 0 | Z6: 1830000 | AA6: 0
D7: 미정 | G7: 8월 | H7: 4668770 | I7: 45897
G8: 8월 | H8: 4668777 | I8: 45889
G9: 8월 | H9: 2450884 | I9: 45887
G10: 8월 | H10: 10000 | I10: 45883
G11: 7월 | H11: 2450884 | I11: 45868
G12: 7월 | H12: -1589500 | I12: 45867
G13: 7월 | H13: 4658777 | I13: 45863
G14: 7월 | H14: 1589500 | I14: 45861
G15: 7월 | H15: 980000 | I15: 45856
G16: 7월 | H16: 67560 | I16: 45856
G17: 6월 | H17: 3405260 | I17: 45831
G18: 5월 | H18: 3405260 | I18: 45798
G19: 4월 | H19: 3405260 | I19: 45776
G20: 4월 | H20: 3405260 | I20: 45761
B23: 소계 | E23: =SUM(E4:E14) -> 0 | H23: =SUM(H6:H16) -> 35220500
B24: 인센티브 | C24: =예산!G20 -> 93360000 | H24: =C24 -> 93360000
B25: 소계 | E25: =$C24 -> 93360000 | H25: =SUM(H24) -> 93360000
A26: 소계 (인건비) | C26: =C4+C24 -> 216130857 | E26: =C26 -> 216130857 | H26: =H23+H25 -> 128580500 | K26: =H26/C26 -> 0.59491968
A27: 학생인건비 | B27: 학생인건비 | C27: =예산!G27 -> 179000000 | G27: 11월 | H27: -8100000 | I27: 45988
G28: 11월 | H28: -8100000 | I28: 45988
G29: 11월 | H29: 84100000 | I29: 45967
G30: 6월 | H30: 118900000 | I30: 45812
A39: 소계 (학생인건비) | C39: =C27 -> 179000000 | E39: =C39 -> 179000000 | H39: =SUM(H27:H38) -> 186800000 | K39: =H39/C39 -> 1.0435754
A40: 연구시설장비비 | B40: 연구시설 장비구입 및 임차비 | C40: 광학현미경 | G40: 11월 | H40: 21990000 | I40: 45985
C41: 프로브스테이션 수리비 | G41: 11월 | H41: 165000 | I41: 45981
C42: 나라장터수수료 스위치매트릭스 | G42: 11월 | H42: 30000 | I42: 45978
C43: 엘립소미터 | G43: 10월 | H43: 42988000 | I43: 45947 | J43: 9월까지의 장비 | K43: =SUM(H40:H43,H47:H48)/A2 -> 0.034881275
C44: 나라장터수수료 GPU | G44: 9월 | H44: 30000 | I44: 45918
C45: 나라장터수수료 B1500 | G45: 9월 | H45: 30000 | I45: 45918 | J45: 하반기 장비 | K45: =SUM(H44:H46)/A2 -> 3.044243e-05
C46: 나라장터수수료 프로브스테이션 | G46: 9월 | H46: 30000 | I46: 45918
C47: 스핀코터 | G47: 9월 | H47: 8030000 | I47: 45910
C48: 홀효과측정기 | G48: 7월 | H48: 29920000 | I48: 45863
C49: 펄스모듈 | G49: 5월 | H49: 186410400 | I49: 45791
B51: 소계 | H51: =SUM(H40:H48) -> 103213000
...

Sheet 이월금일정
A1: 2차년도 이월금 집행내역 | O1: 일자별 누적 기록
A2: =예산!L3 -> 485690651 | J2: = 예상 이월금 | O2: 날짜 | P2: 인건비 | R2: 학생인건비 | T2: 연구시설장비비 | V2: 연구재료비 | X2: 연구활동비 | Z2: 총계
A3: 항목 | B3: 세목 | C3: 3차년도 예산 | D3: 세부집행 계획 | G3: 실제 집행내역 | H3: 집행액 (RCMS 기준) | I3: 집행일 | J3: 집행잔액 | K3: 집행률 | O3: 현황 | P3: =H18 -> 4028892 | Q3: =K18 -> 1 | R3: =H30 -> 0 | S3: =K30 -> #DIV/0! | T3: =H41 -> 186410400 | U3: =K41 -> 0.66009767 | V3: =H48 -> 0 | W3: =K48 -> 0 | X3: =H87 -> 0 | Y3: =K87 -> 0 | Z3: =H88 -> 190439292 | AA3: =K88 -> 0.39209997
A4: 인건비 | B4: 직원인건비 | C4: =예산!P5 -> 4028892 | D4: 전미자 | E4: =예산!P7 -> 2439392 | G4: 3월 | H4: =예산!N7+예산!N8 -> 3405260 | I4: 45776 | O4: 45793 | P4: 4028892 | Q4: 1 | R4: 0 | S4: 0 | T4: 186410400 | U4: 0.66009767 | V4: 0 | W4: 0 | X4: 0 | Y4: 0 | Z4: 190439292 | AA4: 0.39209997
D5: 강훈경 | E5: =예산!P8 -> 1589500 | G5: 4월 | H5: =예산!N7-1192128 -> 623632
D6: 미정
D7: 미정
B15: 소계 | E15: =SUM(E4:E14) -> 4028892 | H15: =SUM(H4:H14) -> 4028892
B16: 인센티브
B17: 소계 | E17: =$C16 -> 0 | H17: 0
A18: 소계 (인건비) | C18: =예산!P5 -> 4028892 | E18: =C18 -> 4028892 | H18: =H15+H17 -> 4028892 | K18: =H18/C18 -> 1
A19: 학생인건비 | B19: 학생인건비
A30: 소계 (학생인건비) | C30: =C19 -> 0 | E30: =C30 -> 0 | H30: =SUM(H19:H29) -> 0 | K30: =H30/C30 -> #DIV/0!
A31: 연구시설장비비 | B31: 연구시설 장비구입 및 임차비 | C31: =예산!P27 -> 282398210 | D31: WGFMU | E31: =예산!P31 -> 186410400 | H31: 186410400
D32: GPU 1대 (첨융) | E32: =예산!P30 -> 95987810 | H32: 0
B36: 소계 | E36: =SUM(E31:E35) -> 282398210 | H36: =SUM(H31:H35) -> 186410400
B37: 환경구축비
B40: 소계
A41: 소계 (연구시설장비비) | C41: =예산!P27 -> 282398210 | E41: =SUM(E36,E40) -> 282398210 | H41: =H36+H40 -> 186410400 | K41: =H41/C41 -> 0.66009767
A42: 연구재료비 | B42: 공정 재료비 | C42: =예산!P54 -> 1144000 | D42: 4인치 웨이퍼 | E42: =예산!P54 -> 1144000 | H42: 0
B46: 공정 수행 비용
A48: 소계 (연구재료비) | C48: =예산!P51 -> 1144000 | E48: =SUM(E42:E47) -> 1144000 | H48: =H45+H47 -> 0 | K48: =H48/C48 -> 0
A49: 연구활동비 | B49: 출장비
B57: 소계 | E57: =SUM(E49:E56) -> 0 | H57: =SUM(H49:H56) -> 0
B58: 인쇄비 | C58: =예산!P103 -> 150000 | D58: 인쇄 및 제본 | E58: =예산!P101 -> 150000 | H58: 0
B59: 소계 | E59: =SUM(E58) -> 150000 | H59: =H58 -> 0
B60: 소프트웨어 활용비 | C60: =예산!P129 -> 157759520 | D60: Cadence | E60: =예산!P127 -> 78879760
D61: Synopsys | E61: =예산!P128 -> 78879760
B71: 소계 | E71: =SUM(E60:E70) -> 157759520 | H71: =SUM(H60:H70) -> 0
B72: 연구실 운영비 | D72: 프린터 토너 | E72: =예산!P94 -> 500000 | H72: 0
D73: A4 용지 | E73: =예산!P95 -> 50000 | H73: 0
D74: 기타 | E74: =예산!P96 -> 60029 | H74: 0
B77: 소계 | E77: =SUM(E72:E76) -> 610029 | H77: =SUM(H72:H76) -> 0
B78: 연구활동 유지비 | C78: =예산!P90 -> 39600000 | D78: EDA 용역 | E78: =예산!P88 -> 18480000 | H78: 0
D79: GPU 용역 | E79: =예산!P89 -> 21120000 | H79: 0
B86: 소계 | E86: =SUM(E78:E85) -> 39600000 | H86: =SUM(H78:H85) -> 0
C87: =예산!P57 -> 198119549 | E87: =SUM(E57,E59,E71,E77,E86) -> 198119549 | H87: =SUM(H57,H59,H71,H77,H86) -> 0 | K87: =H87/C87 -> 0
C88: =SUM(C87,C48,C41,C30,C18) -> 485690651 | H88: =SUM(H87,H48,H41,H30,H18) -> 190439292 | K88: =H88/C88 -> 0.39209997
A122: 소계 (연구활동비)
A123: 전체 총계

Sheet RCMS.260102
A1: 사용일자 | B1: 이체일자 | C1: 등록일자 | D1: 증빙구분 | E1: 비목 | F1: 항목 | G1: 세부항목 | H1: 사용금액 | I1: 사용금액 | J1: 사용금액 | K1: 사용금액 | L1: 이체공급금액 | M1: 이체공급금액 | N1: 이체공급금액 | O1: 이체부가세액 | P1: 이체부가세액 | Q1: 이체부가세액 | R1: 복원공급금액 | S1: 복원공급금액 | T1: 복원공급금액 | U1: 복원부가세액 | V1: 복원부가세액 | W1: 복원부가세액 | X1: 증빙파일 | Y1: 예방도우미 | Z1: 예방도우미 | AA1: 예방도우미 | AB1: 예방도우미 | AC1: 자계좌 이체증빙 | AD1: 연구장비 | AE1: 부가정보 | AF1: 인건비 | AG1: 품목 | AH1: 수입신고필증번호 | AI1: 지급용도 | AJ1: 거래처명 | AK1: 휴폐업 거래처여부 | AL1: 휴폐업 거래처사유 | AM1: 카드 | AN1: 카드 | AO1: 카드 | AP1: 카드 | AQ1: 카드 | AR1: 카드 | AS1: 카드 | AU1: 이체상태 | AV1: 부가세 복원여부 | AW1: 점검메모 | AX1: 상시점검 | AY1: 상시점검 | AZ1: 상시점검 | BA1: 정산 | BB1: 정산 | BC1: 정산 | BD1: 정산 | BE1: 정산 | BF1: 연구개발비 구분 | BG1: 등록구분 | BH1: 지급구분 | BI1: 거래명세서 행정정보
A2: 사용일자 | B2: 이체일자 | C2: 등록일자 | D2: 증빙구분 | E2: 비목 | F2: 항목 | G2: 세부항목 | H2: 사용금액 | I2: 본예산 | J2: 계속비 | K2: 이월금 | L2: 본예산 | M2: 계속비 | N2: 이월금 | O2: 본예산 | P2: 계속비 | Q2: 이월금 | R2: 본예산 | S2: 계속비 | T2: 이월금 | U2: 본예산 | V2: 계속비 | W2: 이월금 | X2: 증빙파일 | Y2: 탐지건수 | Z2: 미확인건수 | AA2: 확인건수 | AB2: 제외건수 | AC2: 자계좌 이체증빙 | AD2: 연구장비 | AE2: 부가정보 | AF2: 인건비 | AG2: 품목 | AH2: 수입신고필증번호 | AI2: 지급용도 | AJ2: 거래처명 | AK2: 휴폐업 거래처여부 | AL2: 휴폐업 거래처사유 | AM2: 카드번호 | AN2: 승인번호 | AO2: 승인일자 | AP2: 매입일자 | AQ2: 결제일자 | AR2: 매입금액 | AS2: 취소건수 | AT2: 취소금액 | AU2: 이체상태 | AV2: 부가세 복원여부 | AW2: 점검메모 | AX2: 점검상태 | AY2: 점검사유 | AZ2: 점검의견 | BA2: 인정상태 | BB2: 보완요청내용 | BC2: 불인정사유구분 | BD2: 불인정사유내용 | BE2: 불인정금액 | BF2: 연구개발비 구분 | BG2: 등록구분 | BH2: 지급구분 | BI2: 거래명세서 행정정보
A3: 2025.12.26 | B3: 2025.12.26 | C3: 2025.12.24 | D3: 기타증빙 | E3: 직접비 | F3: 연구활동비 | G3: 외부 전문기술 활용비 | H3: 2462400 | I3: 2462400 | J3: 0 | K3: 0 | L3: 2462400 | M3: 0 | N3: 0 | O3: 0 | P3: 0 | Q3: 0 | R3: 0 | S3: 0 | T3: 0 | U3: 0 | V3: 0 | W3: 0 | X3: 정상 | Y3: 0 | Z3: 0 | AA3: 0 | AB3: 0 | AE3: 미등록 | AG3: 실수령금액(기타)(실수령액)글로벌장학금-인턴장학금 지급 | AI3: 실수령금액(기타)(실수령액)글로벌장학금-인턴장학금 지급 | AJ3: N | AK3: N | AU3: 집행(이체) 완료 | AV3: N | AW3: 미등록 | AX3: 미확정 | BA3: 미확정 | BF3: 현금 | BG3: 증빙우선 | BH3: 건별지급
A4: 2025.12.26 | B4: 2025.12.26 | C4: 2025.12.24 | D4: 기타증빙 | E4: 직접비 | F4: 연구활동비 | G4: 외부 전문기술 활용비 | H4: 88000 | I4: 88000 | J4: 0 | K4: 0 | L4: 88000 | M4: 0 | N4: 0 | O4: 0 | P4: 0 | Q4: 0 | R4: 0 | S4: 0 | T4: 0 | U4: 0 | V4: 0 | W4: 0 | X4: 정상 | Y4: 0 | Z4: 0 | AA4: 0 | AB4: 0 | AE4: 미등록 | AG4: 공제금액(기타)(소득세외 1건)논문장학금 지급신청: 박정우 1 | AI4: 공제금액(기타)(소득세외 1건)논문장학금 지급신청: 박정우 1 | AJ4: N | AK4: N | AU4: 집행(이체) 완료 | AV4: N | AW4: 미등록 | AX4: 미확정 | BA4: 미확정 | BF4: 현금 | BG4: 증빙우선 | BH4: 건별지급
A5: 2025.12.26 | B5: 2025.12.26 | C5: 2025.12.24 | D5: 기타증빙 | E5: 직접비 | F5: 연구활동비 | G5: 외부 전문기술 활용비 | H5: 912000 | I5: 912000 | J5: 0 | K5: 0 | L5: 912000 | M5: 0 | N5: 0 | O5: 0 | P5: 0 | Q5: 0 | R5: 0 | S5: 0 | T5: 0 | U5: 0 | V5: 0 | W5: 0 | X5: 정상 | Y5: 0 | Z5: 0 | AA5: 0 | AB5: 0 | AE5: 미등록 | AG5: 실수령금액(기타)(실수령액)논문장학금 지급신청: 박정우 1,0 | AI5: 실수령금액(기타)(실수령액)논문장학금 지급신청: 박정우 1,0 | AJ5: N | AK5: N | AU5: 집행(이체) 완료 | AV5: N | AW5: 미등록 | AX5: 미확정 | BA5: 미확정 | BF5: 현금 | BG5: 증빙우선 | BH5: 건별지급
A6: 2025.12.26 | B6: 2025.12.26 | C6: 2025.12.24 | D6: 기타증빙 | E6: 직접비 | F6: 연구활동비 | G6: 외부 전문기술 활용비 | H6: 237600 | I6: 237600 | J6: 0 | K6: 0 | L6: 237600 | M6: 0 | N6: 0 | O6: 0 | P6: 0 | Q6: 0 | R6: 0 | S6: 0 | T6: 0 | U6: 0 | V6: 0 | W6: 0 | X6: 정상 | Y6: 0 | Z6: 0 | AA6: 0 | AB6: 0 | AE6: 미등록 | AG6: 공제금액(기타)(소득세외 1건)글로벌장학금-인턴장학금 지급 | AI6: 공제금액(기타)(소득세외 1건)글로벌장학금-인턴장학금 지급 | AJ6: N | AK6: N | AU6: 집행(이체) 완료 | AV6: N | AW6: 미등록 | AX6: 미확정 | BA6: 미확정 | BF6: 현금 | BG6: 증빙우선 | BH6: 건별지급
A7: 2025.12.24 | B7: 2025.12.24 | C7: 2025.12.22 | D7: 기타증빙 | E7: 직접비 | F7: 연구활동비 | G7: 연구활동비 기타비용 | H7: 600000 | I7: 600000 | J7: 0 | K7: 0 | L7: 600000 | M7: 0 | N7: 0 | O7: 0 | P7: 0 | Q7: 0 | R7: 0 | S7: 0 | T7: 0 | U7: 0 | V7: 0 | W7: 0 | X7: 정상 | Y7: 0 | Z7: 0 | AA7: 0 | AB7: 0 | AG7: [일반지급신청] STOB 리그 팀활동지원비- 서울대학교 에피학 | AI7: [일반지급신청] STOB 리그 팀활동지원비- 서울대학교 에피학 | AJ7: N | AK7: N | AU7: 집행(이체) 완료 | AV7: N | AW7: 미등록 | AX7: 미확정 | BA7: 미확정 | BF7: 현금 | BG7: 증빙우선 | BH7: 건별지급
A8: 2025.12.24 | B8: 2025.12.24 | C8: 2025.12.22 | D8: 기타증빙 | E8: 직접비 | F8: 연구활동비 | G8: 연구활동비 기타비용 | H8: 600000 | I8: 600000 | J8: 0 | K8: 0 | L8: 600000 | M8: 0 | N8: 0 | O8: 0 | P8: 0 | Q8: 0 | R8: 0 | S8: 0 | T8: 0 | U8: 0 | V8: 0 | W8: 0 | X8: 정상 | Y8: 0 | Z8: 0 | AA8: 0 | AB8: 0 | AG8: [일반지급신청] STOB 리그 팀활동지원비- 서울대학교 에피학 | AI8: [일반지급신청] STOB 리그 팀활동지원비- 서울대학교 에피학 | AJ8: N | AK8: N | AU8: 집행(이체) 완료 | AV8: N | AW8: 미등록 | AX8: 미확정 | BA8: 미확정 | BF8: 현금 | BG8: 증빙우선 | BH8: 건별지급
A9: 2025.12.24 | B9: 2025.12.24 | C9: 2025.12.22 | D9: 기타증빙 | E9: 직접비 | F9: 연구활동비 | G9: 연구활동비 기타비용 | H9: 600000 | I9: 600000 | J9: 0 | K9: 0 | L9: 600000 | M9: 0 | N9: 0 | O9: 0 | P9: 0 | Q9: 0 | R9: 0 | S9: 0 | T9: 0 | U9: 0 | V9: 0 | W9: 0 | X9: 정상 | Y9: 0 | Z9: 0 | AA9: 0 | AB9: 0 | AG9: [일반지급신청] STOB 리그 팀활동지원비- 서울대학교 에피학 | AI9: [일반지급신청] STOB 리그 팀활동지원비- 서울대학교 에피학 | AJ9: N | AK9: N | AU9: 집행(이체) 완료 | AV9: N | AW9: 미등록 | AX9: 미확정 | BA9: 미확정 | BF9: 현금 | BG9: 증빙우선 | BH9: 건별지급
A10: 2025.12.24 | B10: 2025.12.24 | C10: 2025.12.22 | D10: 기타증빙 | E10: 직접비 | F10: 연구활동비 | G10: 연구활동비 기타비용 | H10: 600000 | I10: 600000 | J10: 0 | K10: 0 | L10: 600000 | M10: 0 | N10: 0 | O10: 0 | P10: 0 | Q10: 0 | R10: 0 | S10: 0 | T10: 0 | U10: 0 | V10: 0 | W10: 0 | X10: 정상 | Y10: 0 | Z10: 0 | AA10: 0 | AB10: 0 | AG10: [일반지급신청] STOB 리그 팀활동지원비- 서울대학교 에피학 | AI10: [일반지급신청] STOB 리그 팀활동지원비- 서울대학교 에피학 | AJ10: N | AK10: N | AU10: 집행(이체) 완료 | AV10: N | AW10: 미등록 | AX10: 미확정 | BA10: 미확정 | BF10: 현금 | BG10: 증빙우선 | BH10: 건별지급
A11: 2025.12.24 | B11: 2025.12.24 | C11: 2025.12.22 | D11: 기타증빙 | E11: 직접비 | F11: 연구활동비 | G11: 연구활동비 기타비용 | H11: 600000 | I11: 600000 | J11: 0 | K11: 0 | L11: 600000 | M11: 0 | N11: 0 | O11: 0 | P11: 0 | Q11: 0 | R11: 0 | S11: 0 | T11: 0 | U11: 0 | V11: 0 | W11: 0 | X11: 정상 | Y11: 0 | Z11: 0 | AA11: 0 | AB11: 0 | AG11: [일반지급신청] STOB 리그 팀활동지원비- 서울대학교 에피학 | AI11: [일반지급신청] STOB 리그 팀활동지원비- 서울대학교 에피학 | AJ11: N | AK11: N | AU11: 집행(이체) 완료 | AV11: N | AW11: 미등록 | AX11: 미확정 | BA11: 미확정 | BF11: 현금 | BG11: 증빙우선 | BH11: 건별지급
A12: 2025.12.24 | B12: 2025.12.24 | C12: 2025.12.22 | D12: 기타증빙 | E12: 직접비 | F12: 인건비 | G12: 참여연구원 인건비 | H12: 425360 | I12: 425360 | J12: 0 | K12: 0 | L12: 425360 | M12: 0 | N12: 0 | O12: 0 | P12: 0 | Q12: 0 | R12: 0 | S12: 0 | T12: 0 | U12: 0 | V12: 0 | W12: 0 | X12: 정상 | Y12: 0 | Z12: 0 | AA12: 0 | AB12: 0 | AG12: 기관부담금액(건강보험(기관)외 4건)[202512]한호철 등 4명 인 | AI12: 기관부담금액(건강보험(기관)외 4건)[202512]한호철 등 4명 인 | AJ12: N | AK12: N | AU12: 집행(이체) 완료 | AV12: N | AW12: 미등록 | AX12: 미확정 | BA12: 미확정 | BF12: 현금 | BG12: 증빙우선 | BH12: 건별지급
A13: 2025.12.24 | B13: 2025.12.24 | C13: 2025.12.22 | D13: 기타증빙 | E13: 직접비 | F13: 인건비 | G13: 참여연구원 인건비 | H13: 200870 | I13: 200870 | J13: 0 | K13: 0 | L13: 200870 | M13: 0 | N13: 0 | O13: 0 | P13: 0 | Q13: 0 | R13: 0 | S13: 0 | T13: 0 | U13: 0 | V13: 0 | W13: 0 | X13: 정상 | Y13: 0 | Z13: 0 | AA13: 0 | AB13: 0 | AG13: 공제금액(근로)(소득세외 1건)[202512]한호철 등 4명 인건비지 | AI13: 공제금액(근로)(소득세외 1건)[202512]한호철 등 4명 인건비지 | AJ13: N | AK13: N | AU13: 집행(이체) 완료 | AV13: N | AW13: 미등록 | AX13: 미확정 | BA13: 미확정 | BF13: 현금 | BG13: 증빙우선 | BH13: 건별지급
A14: 2025.12.24 | B14: 2025.12.24 | C14: 2025.12.22 | D14: 기타증빙 | E14: 직접비 | F14: 인건비 | G14: 참여연구원 인건비 | H14: 243050 | I14: 243050 | J14: 0 | K14: 0 | L14: 243050 | M14: 0 | N14: 0 | O14: 0 | P14: 0 | Q14: 0 | R14: 0 | S14: 0 | T14: 0 | U14: 0 | V14: 0 | W14: 0 | X14: 정상 | Y14: 0 | Z14: 0 | AA14: 0 | AB14: 0 | AG14: 퇴직적립금액(퇴직적립금)[202512]한호철 등 4명 인건비지급내 | AI14: 퇴직적립금액(퇴직적립금)[202512]한호철 등 4명 인건비지급내 | AJ14: N | AK14: N | AU14: 집행(이체) 완료 | AV14: N | AW14: 미등록 | AX14: 미확정 | BA14: 미확정 | BF14: 현금 | BG14: 증빙우선 | BH14: 건별지급
A15: 2025.12.24 | B15: 2025.12.24 | C15: 2025.12.22 | D15: 기타증빙 | E15: 직접비 | F15: 인건비 | G15: 참여연구원 인건비 | H15: 326417 | I15: 326417 | J15: 0 | K15: 0 | L15: 326417 | M15: 0 | N15: 0 | O15: 0 | P15: 0 | Q15: 0 | R15: 0 | S15: 0 | T15: 0 | U15: 0 | V15: 0 | W15: 0 | X15: 정상 | Y15: 0 | Z15: 0 | AA15: 0 | AB15: 0 | AG15: 퇴직적립금액(퇴직적립금)[202512]한호철 등 4명 인건비지급내 | AI15: 퇴직적립금액(퇴직적립금)[202512]한호철 등 4명 인건비지급내 | AJ15: N | AK15: N | AU15: 집행(이체) 완료 | AV15: N | AW15: 미등록 | AX15: 미확정 | BA15: 미확정 | BF15: 현금 | BG15: 증빙우선 | BH15: 건별지급
A16: 2025.12.24 | B16: 2025.12.24 | C16: 2025.12.22 | D16: 기타증빙 | E16: 직접비 | F16: 인건비 | G16: 참여연구원 인건비 | H16: 368340 | I16: 368340 | J16: 0 | K16: 0 | L16: 368340 | M16: 0 | N16: 0 | O16: 0 | P16: 0 | Q16: 0 | R16: 0 | S16: 0 | T16: 0 | U16: 0 | V16: 0 | W16: 0 | X16: 정상 | Y16: 0 | Z16: 0 | AA16: 0 | AB16: 0 | AG16: 공제금액(근로)(건강보험외 3건)[202512]한호철 등 4명 인건비 | AI16: 공제금액(근로)(건강보험외 3건)[202512]한호철 등 4명 인건비 | AJ16: N | AK16: N | AU16: 집행(이체) 완료 | AV16: N | AW16: 미등록 | AX16: 미확정 | BA16: 미확정 | BF16: 현금 | BG16: 증빙우선 | BH16: 건별지급
A17: 2025.12.24 | B17: 2025.12.24 | C17: 2025.12.22 | D17: 기타증빙 | E17: 직접비 | F17: 인건비 | G17: 참여연구원 인건비 | H17: 3347790 | I17: 3347790 | J17: 0 | K17: 0 | L17: 3347790 | M17: 0 | N17: 0 | O17: 0 | P17: 0 | Q17: 0 | R17: 0 | S17: 0 | T17: 0 | U17: 0 | V17: 0 | W17: 0 | X17: 정상 | Y17: 0 | Z17: 0 | AA17: 0 | AB17: 0 | AG17: 실수령금액(근로)(실수령액)[202512]한호철 등 4명 인건비지급 | AI17: 실수령금액(근로)(실수령액)[202512]한호철 등 4명 인건비지급 | AJ17: N | AK17: N | AU17: 집행(이체) 완료 | AV17: N | AW17: 미등록 | AX17: 미확정 | BA17: 미확정 | BF17: 현금 | BG17: 증빙우선 | BH17: 건별지급
A18: 2025.12.24 | B18: 2025.12.24 | C18: 2025.12.22 | D18: 기타증빙 | E18: 직접비 | F18: 인건비 | G18: 참여연구원 인건비 | H18: 316700 | I18: 316700 | J18: 0 | K18: 0 | L18: 316700 | M18: 0 | N18: 0 | O18: 0 | P18: 0 | Q18: 0 | R18: 0 | S18: 0 | T18: 0 | U18: 0 | V18: 0 | W18: 0 | X18: 정상 | Y18: 0 | Z18: 0 | AA18: 0 | AB18: 0 | AG18: 기관부담금액(건강보험(기관)외 4건)[202512]한호철 등 4명 인 | AI18: 기관부담금액(건강보험(기관)외 4건)[202512]한호철 등 4명 인 | AJ18: N | AK18: N | AU18: 집행(이체) 완료 | AV18: N | AW18: 미등록 | AX18: 미확정 | BA18: 미확정 | BF18: 현금 | BG18: 증빙우선 | BH18: 건별지급
... A31: 2025.12.24 | B31: 2025.12.24 | C31: 2025.12.22 | D31: 기타증빙 | E31: 직접비 | F31: 인건비 | G31: 참여연구원 인건비 | H31: 3347790 | I31: 3347790 | J31: 0 | K31: 0 | L31: 3347790 | M31: 0 | N31: 0 | O31: 0 | P31: 0 | Q31: 0 | R31: 0 | S31: 0 | T31: 0 | U31: 0 | V31: 0 | W31: 0 | X31: 정상 | Y31: 0 | Z31: 0 | AA31: 0 | AB31: 0 | AG31: 실수령금액(근로)(실수령액)[202512]한호철 등 4명 인건비지급 | AI31: 실수령금액(근로)(실수령액)[202512]한호철 등 4명 인건비지급 | AJ31: N | AK31: N | AU31: 집행(이체) 완료 | AV31: N | AW31: 미등록 | AX31: 미확정 | BA31: 미확정 | BF31: 현금 | BG31: 증빙우선 | BH31: 건별지급
A32: 2025.12.18 | B32: 2025.12.26 | C32: 2025.12.26 | D32: 카드결제 | E32: 직접비 | F32: 연구활동비 | G32: 연구활동비 기타비용 | H32: 3080000 | I32: 3080000 | J32: 0 | K32: 0 | L32: 2800000 | M32: 0 | N32: 0 | O32: 280000 | P32: 0 | Q32: 0 | R32: 0 | S32: 0 | T32: 0 | U32: 0 | V32: 0 | W32: 0 | X32: 정상 | Y32: 0 | Z32: 0 | AA32: 0 | AB32: 0 | AG32: [구매지출신청] 뉴로모틱 반도체 기술 교재 출력비 등 총 2 | AI32: [구매지출신청] 뉴로모틱 반도체 기술 교재 출력비 등 총 2 | AJ32: 시스템프로 | AK32: N | AM32: 5525-7642-1699-1980 | AN32: 49297402 | AO32: 2025.12.18 | AP32: 2025.12.19 | AQ32: 2026.01.15 | AR32: 3080000 | AS32: 0 | AT32: 0 | AU32: 집행(이체) 완료 | AV32: N | AW32: 미등록 | AX32: 미확정 | BA32: 미확정 | BF32: 현금 | BG32: 증빙우선 | BH32: 건별지급
A33: 2025.12.18 | B33: 2025.12.26 | C33: 2025.12.24 | D33: 카드결제 | E33: 직접비 | F33: 연구활동비 | G33: 연구실운영비 | H33: 465000 | I33: 465000 | J33: 0 | K33: 0 | L33: 422728 | M33: 0 | N33: 0 | O33: 42272 | P33: 0 | Q33: 0 | R33: 0 | S33: 0 | T33: 0 | U33: 0 | V33: 0 | W33: 0 | X33: 정상 | Y33: 0 | Z33: 0 | AA33: 0 | AB33: 0 | AG33: [구매지출신청] 캐논 CRG 054 H 세트 토너 MF645Cx MF643Cdw LBP62 | AI33: [구매지출신청] 캐논 CRG 054 H 세트 토너 MF645Cx MF643Cdw LBP62 | AJ33: 네이버파이낸셜（주） | AK33: N | AM33: 5525-7642-1944-6438 | AN33: 46656372 | AO33: 2025.12.18 | AP33: 2025.12.19 | AQ33: 2026.01.15 | AR33: 465000 | AS33: 0 | AT33: 0 | AU33: 집행(이체) 완료 | AV33: N | AW33: 미등록 | AX33: 미확정 | BA33: 미확정 | BF33: 현금 | BG33: 증빙우선 | BH33: 건별지급
A34: 2025.12.18 | B34: 2025.12.18 | C34: 2025.12.17 | D34: 기타증빙 | E34: 직접비 | F34: 연구시설·장비비 | G34: 연구시설ㆍ장비 구입ㆍ설치비 | H34: 30000 | I34: 30000 | J34: 0 | K34: 0 | L34: 30000 | M34: 0 | N34: 0 | O34: 0 | P34: 0 | Q34: 0 | R34: 0 | S34: 0 | T34: 0 | U34: 0 | V34: 0 | W34: 0 | X34: 정상 | Y34: 0 | Z34: 0 | AA34: 0 | AB34: 0 | AD34: 예외등록 | AG34: [구매지출신청] 진공증착기 구입시 나라장터 이용수수료 등 | AI34: [구매지출신청] 진공증착기 구입시 나라장터 이용수수료 등 | AJ34: N | AK34: N | AU34: 집행(이체) 완료 | AV34: N | AW34: 미등록 | AX34: 미확정 | BA34: 미확정 | BF34: 현금 | BG34: 증빙우선 | BH34: 건별지급
A35: 2025.12.24 | B35: 2025.12.26 | C35: 2025.12.24 | D35: 전자(세금)계산서 | E35: 직접비 | F35: 연구재료비 | G35: 연구재료 구입비 | H35: 5500000 | I35: 5500000 | J35: 0 | K35: 0 | L35: 5000000 | M35: 0 | N35: 0 | O35: 500000 | P35: 0 | Q35: 0 | R35: 0 | S35: 0 | T35: 0 | U35: 0 | V35: 0 | W35: 0 | X35: 정상 | Y35: 0 | Z35: 0 | AA35: 0 | AB35: 0 | AG35: [구매지출신청] Quartz chrome mask 등 총 1건 | AI35: [구매지출신청] Quartz chrome mask 등 총 1건 | AJ35: (주)마이크로이미지 | AK35: N | AU35: 집행(이체) 완료 | AV35: N | AW35: 미등록 | AX35: 미확정 | BA35: 미확정 | BF35: 현금 | BG35: 증빙우선 | BH35: 건별지급
A36: 2025.12.05 | B36: 2025.12.26 | C36: 2025.12.24 | D36: 카드결제 | E36: 직접비 | F36: 연구활동비 | G36: 연구실운영비 | H36: 73100 | I36: 73100 | J36: 0 | K36: 0 | L36: 66455 | M36: 0 | N36: 0 | O36: 6645 | P36: 0 | Q36: 0 | R36: 0 | S36: 0 | T36: 0 | U36: 0 | V36: 0 | W36: 0 | X36: 정상 | Y36: 0 | Z36: 0 | AA36: 0 | AB36: 0 | AG36: [구매지출신청] 에너자이저 맥스 건전지(AA18/18개입/LR06/알카 | AI36: [구매지출신청] 에너자이저 맥스 건전지(AA18/18개입/LR06/알카 | AJ36: （주）오피스디포코리아 | AK36: N | AM36: 5525-7642-1944-6438 | AN36: 26115468 | AO36: 2025.12.05 | AP36: 2025.12.06 | AQ36: 2026.01.15 | AR36: 73100 | AS36: 0 | AT36: 0 | AU36: 집행(이체) 완료 | AV36: N | AW36: 미등록 | AX36: 미확정 | BA36: 미확정 | BF36: 현금 | BG36: 증빙우선 | BH36: 건별지급
A37: 2025.12.08 | B37: 2025.12.08 | C37: 2025.12.08 | D37: 기타증빙 | E37: 직접비 | F37: 연구활동비 | G37: 연구활동비 기타비용 | H37: 60000 | I37: 60000 | J37: 0 | K37: 0 | L37: 60000 | M37: 0 | N37: 0 | O37: 0 | P37: 0 | Q37: 0 | R37: 0 | S37: 0 | T37: 0 | U37: 0 | V37: 0 | W37: 0 | X37: 정상 | Y37: 0 | Z37: 0 | AA37: 0 | AB37: 0 | AG37: [일반지급신청] [반도체특성화대학] ICCE-Asia 2025 학회 등록 25 | AI37: [일반지급신청] [반도체특성화대학] ICCE-Asia 2025 학회 등록 25 | AJ37: N | AK37: N | AU37: 집행(이체) 완료 | AV37: N | AW37: 미등록 | AX37: 미확정 | BA37: 미확정 | BF37: 현금 | BG37: 증빙우선 | BH37: 건별지급
A38: 2025.12.08 | B38: 2025.12.08 | C38: 2025.12.08 | D38: 기타증빙 | E38: 직접비 | F38: 연구활동비 | G38: 연구활동비 기타비용 | H38: 60000 | I38: 60000 | J38: 0 | K38: 0 | L38: 60000 | M38: 0 | N38: 0 | O38: 0 | P38: 0 | Q38: 0 | R38: 0 | S38: 0 | T38: 0 | U38: 0 | V38: 0 | W38: 0 | X38: 정상 | Y38: 0 | Z38: 0 | AA38: 0 | AB38: 0 | AG38: [일반지급신청] [반도체특성화대학] ICCE-Asia 2025 학회 등록 25 | AI38: [일반지급신청] [반도체특성화대학] ICCE-Asia 2025 학회 등록 25 | AJ38: N | AK38: N | AU38: 집행(이체) 완료 | AV38: N | AW38: 미등록 | AX38: 미확정 | BA38: 미확정 | BF38: 현금 | BG38: 증빙우선 | BH38: 건별지급
A39: 2025.12.08 | B39: 2025.12.08 | C39: 2025.12.08 | D39: 기타증빙 | E39: 직접비 | F39: 연구활동비 | G39: 연구활동비 기타비용 | H39: 60000 | I39: 60000 | J39: 0 | K39: 0 | L39: 60000 | M39: 0 | N39: 0 | O39: 0 | P39: 0 | Q39: 0 | R39: 0 | S39: 0 | T39: 0 | U39: 0 | V39: 0 | W39: 0 | X39: 정상 | Y39: 0 | Z39: 0 | AA39: 0 | AB39: 0 | AG39: [일반지급신청] [반도체특성화대학] ICCE-Asia 2025 학회 등록 25 | AI39: [일반지급신청] [반도체특성화대학] ICCE-Asia 2025 학회 등록 25 | AJ39: N | AK39: N | AU39: 집행(이체) 완료 | AV39: N | AW39: 미등록 | AX39: 미확정 | BA39: 미확정 | BF39: 현금 | BG39: 증빙우선 | BH39: 건별지급
A40: 2025.12.08 | B40: 2025.12.08 | C40: 2025.12.08 | D40: 기타증빙 | E40: 직접비 | F40: 연구활동비 | G40: 연구활동비 기타비용 | H40: 60000 | I40: 60000 | J40: 0 | K40: 0 | L40: 60000 | M40: 0 | N40: 0 | O40: 0 | P40: 0 | Q40: 0 | R40: 0 | S40: 0 | T40: 0 | U40: 0 | V40: 0 | W40: 0 | X40: 정상 | Y40: 0 | Z40: 0 | AA40: 0 | AB40: 0 | AG40: [일반지급신청] [반도체특성화대학] ICCE-Asia 2025 학회 등록 25 | AI40: [일반지급신청] [반도체특성화대학] ICCE-Asia 2025 학회 등록 25 | AJ40: N | AK40: N | AU40: 집행(이체) 완료 | AV40: N | AW40: 미등록 | AX40: 미확정 | BA40: 미확정 | BF40: 현금 | BG40: 증빙우선 | BH40: 건별지급
A41: 2025.12.08 | B41: 2025.12.08 | C41: 2025.12.08 | D41: 기타증빙 | E41: 직접비 | F41: 연구활동비 | G41: 연구활동비 기타비용 | H41: 150000 | I41: 150000 | J41: 0 | K41: 0 | L41: 150000 | M41: 0 | N41: 0 | O41: 0 | P41: 0 | Q41: 0 | R41: 0 | S41: 0 | T41: 0 | U41: 0 | V41: 0 | W41: 0 | X41: 정상 | Y41: 0 | Z41: 0 | AA41: 0 | AB41: 0 | AG41: [일반지급신청] [반도체특성화대학] ICCE-Asia 2025 학회 등록 25 | AI41: [일반지급신청] [반도체특성화대학] ICCE-Asia 2025 학회 등록 25 | AJ41: N | AK41: N | AU41: 집행(이체) 완료 | AV41: N | AW41: 미등록 | AX41: 미확정 | BA41: 미확정 | BF41: 현금 | BG41: 증빙우선 | BH41: 건별지급
A42: 2025.12.08 | B42: 2025.12.08 | C42: 2025.12.08 | D42: 기타증빙 | E42: 직접비 | F42: 연구활동비 | G42: 연구활동비 기타비용 | H42: 60000 | I42: 60000 | J42: 0 | K42: 0 | L42: 60000 | M42: 0 | N42: 0 | O42: 0 | P42: 0 | Q42: 0 | R42: 0 | S42: 0 | T42: 0 | U42: 0 | V42: 0 | W42: 0 | X42: 정상 | Y42: 0 | Z42: 0 | AA42: 0 | AB42: 0 | AG42: [일반지급신청] [반도체특성화대학] ICCE-Asia 2025 학회 등록 25 | AI42: [일반지급신청] [반도체특성화대학] ICCE-Asia 2025 학회 등록 25 | AJ42: N | AK42: N | AU42: 집행(이체) 완료 | AV42: N | AW42: 미등록 | AX42: 미확정 | BA42: 미확정 | BF42: 현금 | BG42: 증빙우선 | BH42: 건별지급
A43: 2025.12.08 | B43: 2025.12.08 | C43: 2025.12.08 | D43: 기타증빙 | E43: 직접비 | F43: 연구활동비 | G43: 연구활동비 기타비용 | H43: 60000 | I43: 60000 | J43: 0 | K43: 0 | L43: 60000 | M43: 0 | N43: 0 | O43: 0 | P43: 0 | Q43: 0 | R43: 0 | S43: 0 | T43: 0 | U43: 0 | V43: 0 | W43: 0 | X43: 정상 | Y43: 0 | Z43: 0 | AA43: 0 | AB43: 0 | AG43: [일반지급신청] [반도체특성화대학] ICCE-Asia 2025 학회 등록 25 | AI43: [일반지급신청] [반도체특성화대학] ICCE-Asia 2025 학회 등록 25 | AJ43: N | AK43: N | AU43: 집행(이체) 완료 | AV43: N | AW43: 미등록 | AX43: 미확정 | BA43: 미확정 | BF43: 현금 | BG43: 증빙우선 | BH43: 건별지급
A44: 2025.12.08 | B44: 2025.12.08 | C44: 2025.12.08 | D44: 기타증빙 | E44: 직접비 | F44: 연구활동비 | G44: 연구활동비 기타비용 | H44: 60000 | I44: 60000 | J44: 0 | K44: 0 | L44: 60000 | M44: 0 | N44: 0 | O44: 0 | P44: 0 | Q44: 0 | R44: 0 | S44: 0 | T44: 0 | U44: 0 | V44: 0 | W44: 0 | X44: 정상 | Y44: 0 | Z44: 0 | AA44: 0 | AB44: 0 | AG44: [일반지급신청] [반도체특성화대학] ICCE-Asia 2025 학회 등록 25 | AI44: [일반지급신청] [반도체특성화대학] ICCE-Asia 2025 학회 등록 25 | AJ44: N | AK44: N | AU44: 집행(이체) 완료 | AV44: N | AW44: 미등록 | AX44: 미확정 | BA44: 미확정 | BF44: 현금 | BG44: 증빙우선 | BH44: 건별지급
A45: 2025.12.08 | B45: 2025.12.08 | C45: 2025.12.08 | D45: 기타증빙 | E45: 직접비 | F45: 연구활동비 | G45: 연구활동비 기타비용 | H45: 60000 | I45: 60000 | J45: 0 | K45: 0 | L45: 60000 | M45: 0 | N45: 0 | O45: 0 | P45: 0 | Q45: 0 | R45: 0 | S45: 0 | T45: 0 | U45: 0 | V45: 0 | W45: 0 | X45: 정상 | Y45: 0 | Z45: 0 | AA45: 0 | AB45: 0 | AG45: [일반지급신청] [반도체특성화대학] ICCE-Asia 2025 학회 등록 25 | AI45: [일반지급신청] [반도체특성화대학] ICCE-Asia 2025 학회 등록 25 | AJ45: N | AK45: N | AU45: 집행(이체) 완료 | AV45: N | AW45: 미등록 | AX45: 미확정 | BA45: 미확정 | BF45: 현금 | BG45: 증빙우선 | BH45: 건별지급
A46: 2025.12.08 | B46: 2025.12.08 | C46: 2025.12.08 | D46: 기타증빙 | E46: 직접비 | F46: 연구활동비 | G46: 연구활동비 기타비용 | H46: 60000 | I46: 60000 | J46: 0 | K46: 0 | L46: 60000 | M46: 0 | N46: 0 | O46: 0 | P46: 0 | Q46: 0 | R46: 0 | S46: 0 | T46: 0 | U46: 0 | V46: 0 | W46: 0 | X46: 정상 | Y46: 0 | Z46: 0 | AA46: 0 | AB46: 0 | AG46: [일반지급신청] [반도체특성화대학] ICCE-Asia 2025 학회 등록 25 | AI46: [일반지급신청] [반도체특성화대학] ICCE-Asia 2025 학회 등록 25 | AJ46: N | AK46: N | AU46: 집행(이체) 완료 | AV46: N | AW46: 미등록 | AX46: 미확정 | BA46: 미확정 | BF46: 현금 | BG46: 증빙우선 | BH46: 건별지급
A47: 2025.12.08 | B47: 2025.12.08 | C47: 2025.12.08 | D47: 기타증빙 | E47: 직접비 | F47: 연구활동비 | G47: 연구활동비 기타비용 | H47: 60000 | I47: 60000 | J47: 0 | K47: 0 | L47: 60000 | M47: 0 | N47: 0 | O47: 0 | P47: 0 | Q47: 0 | R47: 0 | S47: 0 | T47: 0 | U47: 0 | V47: 0 | W47: 0 | X47: 정상 | Y47: 0 | Z47: 0 | AA47: 0 | AB47: 0 | AG47: [일반지급신청] [반도체특성화대학] ICCE-Asia 2025 학회 등록 25 | AI47: [일반지급신청] [반도체특성화대학] ICCE-Asia 2025 학회 등록 25 | AJ47: N | AK47: N | AU47: 집행(이체) 완료 | AV47: N | AW47: 미등록 | AX47: 미확정 | BA47: 미확정 | BF47: 현금 | BG47: 증빙우선 | BH47: 건별지급
A48: 2025.12.08 | B48: 2025.12.08 | C48: 2025.12.08 | D48: 기타증빙 | E48: 직접비 | F48: 연구활동비 | G48: 연구활동비 기타비용 | H48: 60000 | I48: 60000 | J48: 0 | K48: 0 | L48: 60000 | M48: 0 | N48: 0 | O48: 0 | P48: 0 | Q48: 0 | R48: 0 | S48: 0 | T48: 0 | U48: 0 | V48: 0 | W48: 0 | X48: 정상 | Y48: 0 | Z48: 0 | AA48: 0 | AB48: 0 | AG48: [일반지급신청] [반도체특성화대학] ICCE-Asia 2025 학회 등록 25 | AI48: [일반지급신청] [반도체특성화대학] ICCE-Asia 2025 학회 등록 25 | AJ48: N | AK48: N | AU48: 집행(이체) 완료 | AV48: N | AW48: 미등록 | AX48: 미확정 | BA48: 미확정 | BF48: 현금 | BG48: 증빙우선 | BH48: 건별지급
... A66: 2025.12.24 | B66: 2025.12.26 | C66: 2025.12.24 | D66: 전자(세금)계산서 | E66: 직접비 | F66: 연구재료비 | G66: 연구재료 구입비 | H66: 453970 | I66: 453970 | J66: 0 | K66: 0 | L66: 412700 | M66: 0 | N66: 0 | O66: 41270 | P66: 0 | Q66: 0 | R66: 0 | S66: 0 | T66: 0 | U66: 0 | V66: 0 | W66: 0 | X66: 정상 | Y66: 0 | Z66: 0 | AA66: 0 | AB66: 0 | AG66: [구매지출신청] 4inch Single Wafer Tray 외 총 4건 | AI66: [구매지출신청] 4inch Single Wafer Tray 외 총 4건 | AJ66: (주)아이넥서스 | AK66: N | AU66: 집행(이체) 완료 | AV66: N | AW66: 미등록 | AX66: 미확정 | BA66: 미확정 | BF66: 현금 | BG66: 증빙우선 | BH66: 건별지급
A67: 2025.12.05 | B67: 2025.12.08 | C67: 2025.12.05 | D67: 전자(세금)계산서 | E67: 직접비 | F67: 연구시설·장비비 | G67: 연구시설ㆍ장비 구입ㆍ설치비 | H67: 506088000 | I67: 410100190 | J67: 0 | K67: 95987810 | L67: 372818355 | M67: 0 | N67: 87261645 | O67: 37281835 | P67: 0 | Q67: 8726165 | R67: 0 | S67: 0 | T67: 0 | U67: 0 | V67: 0 | W67: 0 | X67: 정상 | Y67: 0 | Z67: 0 | AA67: 0 | AB67: 0 | AD67: 시설 | AG67: 컴퓨터서버 구입비 | AI67: 컴퓨터서버 구입비 | AJ67: 주)디에스앤지 | AK67: N | AU67: 집행(이체) 완료 | AV67: N | AW67: 미등록 | AX67: 미확정 | BA67: 미확정 | BF67: 현금 | BG67: 증빙우선 | BH67: 건별지급
A68: 2025.11.28 | B68: 2025.11.28 | C68: 2025.11.27 | D68: 기타증빙 | E68: 직접비 | F68: 연구활동비 | G68: 출장비 | H68: 83700 | I68: 83700 | J68: 0 | K68: 0 | L68: 83700 | M68: 0 | N68: 0 | O68: 0 | P68: 0 | Q68: 0 | R68: 0 | S68: 0 | T68: 0 | U68: 0 | V68: 0 | W68: 0 | X68: 정상 | Y68: 0 | Z68: 0 | AA68: 0 | AB68: 0 | AE68: 미등록 | AG68: 윤상원 외 0건 | AI68: 윤상원 외 0건 | AJ68: N | AK68: N | AU68: 집행(이체) 완료 | AV68: N | AW68: 미등록 | AX68: 미흡 | AY68: 증빙 자료 미비 | AZ68: 해당사업비카드 미사용 불인정 대상입니다. 타과제에서 미사용 내역 확인 바랍니다. | BA68: 미확정 | BF68: 현금 | BG68: 증빙우선 | BH68: 건별지급
A69: 2025.11.28 | B69: 2025.11.28 | C69: 2025.11.27 | D69: 기타증빙 | E69: 직접비 | F69: 연구활동비 | G69: 출장비 | H69: 70000 | I69: 70000 | J69: 0 | K69: 0 | L69: 70000 | M69: 0 | N69: 0 | O69: 0 | P69: 0 | Q69: 0 | R69: 0 | S69: 0 | T69: 0 | U69: 0 | V69: 0 | W69: 0 | X69: 정상 | Y69: 0 | Z69: 0 | AA69: 0 | AB69: 0 | AE69: 미등록 | AG69: 윤상원 외 0건 | AI69: 윤상원 외 0건 | AJ69: N | AK69: N | AU69: 집행(이체) 완료 | AV69: N | AW69: 미등록 | AX69: 정상 | BA69: 미확정 | BF69: 현금 | BG69: 증빙우선 | BH69: 건별지급
...

Sheet RCMS.260112
A1: 사용일자 | B1: 이체일자 | C1: 등록일자 | D1: 증빙구분 | E1: 비목 | F1: 항목 | G1: 세부항목 | H1: 사용금액 | I1: 사용금액 | J1: 사용금액 | K1: 사용금액 | L1: 이체공급금액 | M1: 이체공급금액 | N1: 이체공급금액 | O1: 이체부가세액 | P1: 이체부가세액 | Q1: 이체부가세액 | R1: 복원공급금액 | S1: 복원공급금액 | T1: 복원공급금액 | U1: 복원부가세액 | V1: 복원부가세액 | W1: 복원부가세액 | X1: 증빙파일 | Y1: 예방도우미 | Z1: 예방도우미 | AA1: 예방도우미 | AB1: 예방도우미 | AC1: 자계좌 이체증빙 | AD1: 연구장비 | AE1: 부가정보 | AF1: 인건비 | AG1: 품목 | AH1: 수입신고필증번호 | AI1: 지급용도 | AJ1: 거래처명 | AK1: 휴폐업 거래처여부 | AL1: 휴폐업 거래처사유 | AM1: 카드 | AN1: 카드 | AO1: 카드 | AP1: 카드 | AQ1: 카드 | AR1: 카드 | AS1: 카드 | AU1: 이체상태 | AV1: 부가세 복원여부 | AW1: 점검메모 | AX1: 상시점검 | AY1: 상시점검 | AZ1: 상시점검 | BA1: 정산 | BB1: 정산 | BC1: 정산 | BD1: 정산 | BE1: 정산 | BF1: 연구개발비 구분 | BG1: 등록구분 | BH1: 지급구분 | BI1: 거래명세서 행정정보
A2: 사용일자 | B2: 이체일자 | C2: 등록일자 | D2: 증빙구분 | E2: 비목 | F2: 항목 | G2: 세부항목 | H2: 사용금액 | I2: 본예산 | J2: 계속비 | K2: 이월금 | L2: 본예산 | M2: 계속비 | N2: 이월금 | O2: 본예산 | P2: 계속비 | Q2: 이월금 | R2: 본예산 | S2: 계속비 | T2: 이월금 | U2: 본예산 | V2: 계속비 | W2: 이월금 | X2: 증빙파일 | Y2: 탐지건수 | Z2: 미확인건수 | AA2: 확인건수 | AB2: 제외건수 | AC2: 자계좌 이체증빙 | AD2: 연구장비 | AE2: 부가정보 | AF2: 인건비 | AG2: 품목 | AH2: 수입신고필증번호 | AI2: 지급용도 | AJ2: 거래처명 | AK2: 휴폐업 거래처여부 | AL2: 휴폐업 거래처사유 | AM2: 카드번호 | AN2: 승인번호 | AO2: 승인일자 | AP2: 매입일자 | AQ2: 결제일자 | AR2: 매입금액 | AS2: 취소건수 | AT2: 취소금액 | AU2: 이체상태 | AV2: 부가세 복원여부 | AW2: 점검메모 | AX2: 점검상태 | AY2: 점검사유 | AZ2: 점검의견 | BA2: 인정상태 | BB2: 보완요청내용 | BC2: 불인정사유구분 | BD2: 불인정사유내용 | BE2: 불인정금액 | BF2: 연구개발비 구분 | BG2: 등록구분 | BH2: 지급구분 | BI2: 거래명세서 행정정보
A3: 2025.12.26 | B3: 2025.12.26 | C3: 2025.12.24 | D3: 기타증빙 | E3: 직접비 | F3: 연구활동비 | G3: 외부 전문기술 활용비 | H3: 2462400 | I3: 2462400 | J3: 0 | K3: 0 | L3: 2462400 | M3: 0 | N3: 0 | O3: 0 | P3: 0 | Q3: 0 | R3: 0 | S3: 0 | T3: 0 | U3: 0 | V3: 0 | W3: 0 | X3: 정상 | Y3: 1 | Z3: 1 | AA3: 0 | AB3: 0 | AE3: 미등록 | AG3: 실수령금액(기타)(실수령액)글로벌장학금-인턴장학금 지급 | AI3: 실수령금액(기타)(실수령액)글로벌장학금-인턴장학금 지급 | AJ3: N | AK3: N | AU3: 집행(이체) 완료 | AV3: N | AW3: 미등록 | AX3: 미확정 | BA3: 미확정 | BF3: 현금 | BG3: 증빙우선 | BH3: 건별지급
A4: 2025.12.26 | B4: 2025.12.26 | C4: 2025.12.24 | D4: 기타증빙 | E4: 직접비 | F4: 연구활동비 | G4: 외부 전문기술 활용비 | H4: 88000 | I4: 88000 | J4: 0 | K4: 0 | L4: 88000 | M4: 0 | N4: 0 | O4: 0 | P4: 0 | Q4: 0 | R4: 0 | S4: 0 | T4: 0 | U4: 0 | V4: 0 | W4: 0 | X4: 정상 | Y4: 0 | Z4: 0 | AA4: 0 | AB4: 0 | AE4: 미등록 | AG4: 공제금액(기타)(소득세외 1건)논문장학금 지급신청: 박정우 1 | AI4: 공제금액(기타)(소득세외 1건)논문장학금 지급신청: 박정우 1 | AJ4: N | AK4: N | AU4: 집행(이체) 완료 | AV4: N | AW4: 미등록 | AX4: 미확정 | BA4: 미확정 | BF4: 현금 | BG4: 증빙우선 | BH4: 건별지급
A5: 2025.12.26 | B5: 2025.12.26 | C5: 2025.12.24 | D5: 기타증빙 | E5: 직접비 | F5: 연구활동비 | G5: 외부 전문기술 활용비 | H5: 912000 | I5: 912000 | J5: 0 | K5: 0 | L5: 912000 | M5: 0 | N5: 0 | O5: 0 | P5: 0 | Q5: 0 | R5: 0 | S5: 0 | T5: 0 | U5: 0 | V5: 0 | W5: 0 | X5: 정상 | Y5: 1 | Z5: 1 | AA5: 0 | AB5: 0 | AE5: 미등록 | AG5: 실수령금액(기타)(실수령액)논문장학금 지급신청: 박정우 1,0 | AI5: 실수령금액(기타)(실수령액)논문장학금 지급신청: 박정우 1,0 | AJ5: N | AK5: N | AU5: 집행(이체) 완료 | AV5: N | AW5: 미등록 | AX5: 미확정 | BA5: 미확정 | BF5: 현금 | BG5: 증빙우선 | BH5: 건별지급
A6: 2025.12.26 | B6: 2025.12.26 | C6: 2025.12.24 | D6: 기타증빙 | E6: 직접비 | F6: 연구활동비 | G6: 외부 전문기술 활용비 | H6: 237600 | I6: 237600 | J6: 0 | K6: 0 | L6: 237600 | M6: 0 | N6: 0 | O6: 0 | P6: 0 | Q6: 0 | R6: 0 | S6: 0 | T6: 0 | U6: 0 | V6: 0 | W6: 0 | X6: 정상 | Y6: 1 | Z6: 1 | AA6: 0 | AB6: 0 | AE6: 미등록 | AG6: 공제금액(기타)(소득세외 1건)글로벌장학금-인턴장학금 지급 | AI6: 공제금액(기타)(소득세외 1건)글로벌장학금-인턴장학금 지급 | AJ6: N | AK6: N | AU6: 집행(이체) 완료 | AV6: N | AW6: 미등록 | AX6: 미확정 | BA6: 미확정 | BF6: 현금 | BG6: 증빙우선 | BH6: 건별지급
A7: 2025.12.23 | B7: 2026.01.09 | C7: 2026.01.09 | D7: 카드결제 | E7: 직접비 | F7: 연구활동비 | G7: 연구활동비 기타비용 | H7: 33000 | I7: 33000 | J7: 0 | K7: 0 | L7: 30000 | M7: 0 | N7: 0 | O7: 3000 | P7: 0 | Q7: 0 | R7: 0 | S7: 0 | T7: 0 | U7: 0 | V7: 0 | W7: 0 | X7: 정상 | Y7: 0 | Z7: 0 | AA7: 0 | AB7: 0 | AG7: [구매지출신청] 4차년도 사업계획서_33,000원 | AI7: [구매지출신청] 4차년도 사업계획서_33,000원 | AJ7: 시스템프로 | AK7: N | AM7: 5525-7642-1944-6438 | AN7: 13007851 | AO7: 2025.12.23 | AP7: 2025.12.24 | AQ7: 2026.01.15 | AR7: 33000 | AS7: 0 | AT7: 0 | AU7: 집행(이체) 완료 | AV7: N | AW7: 미등록 | AX7: 미확정 | BA7: 미확정 | BF7: 현금 | BG7: 증빙우선 | BH7: 건별지급
A8: 2025.12.24 | B8: 2025.12.24 | C8: 2025.12.22 | D8: 기타증빙 | E8: 직접비 | F8: 연구활동비 | G8: 연구활동비 기타비용 | H8: 600000 | I8: 600000 | J8: 0 | K8: 0 | L8: 600000 | M8: 0 | N8: 0 | O8: 0 | P8: 0 | Q8: 0 | R8: 0 | S8: 0 | T8: 0 | U8: 0 | V8: 0 | W8: 0 | X8: 정상 | Y8: 1 | Z8: 1 | AA8: 0 | AB8: 0 | AG8: [일반지급신청] STOB 리그 팀활동지원비- 서울대학교 에피학 | AI8: [일반지급신청] STOB 리그 팀활동지원비- 서울대학교 에피학 | AJ8: N | AK8: N | AU8: 집행(이체) 완료 | AV8: N | AW8: 미등록 | AX8: 미확정 | BA8: 미확정 | BF8: 현금 | BG8: 증빙우선 | BH8: 건별지급
A9: 2025.12.24 | B9: 2025.12.24 | C9: 2025.12.22 | D9: 기타증빙 | E9: 직접비 | F9: 연구활동비 | G9: 연구활동비 기타비용 | H9: 600000 | I9: 600000 | J9: 0 | K9: 0 | L9: 600000 | M9: 0 | N9: 0 | O9: 0 | P9: 0 | Q9: 0 | R9: 0 | S9: 0 | T9: 0 | U9: 0 | V9: 0 | W9: 0 | X9: 정상 | Y9: 1 | Z9: 1 | AA9: 0 | AB9: 0 | AG9: [일반지급신청] STOB 리그 팀활동지원비- 서울대학교 에피학 | AI9: [일반지급신청] STOB 리그 팀활동지원비- 서울대학교 에피학 | AJ9: N | AK9: N | AU9: 집행(이체) 완료 | AV9: N | AW9: 미등록 | AX9: 미확정 | BA9: 미확정 | BF9: 현금 | BG9: 증빙우선 | BH9: 건별지급
A10: 2025.12.24 | B10: 2025.12.24 | C10: 2025.12.22 | D10: 기타증빙 | E10: 직접비 | F10: 연구활동비 | G10: 연구활동비 기타비용 | H10: 600000 | I10: 600000 | J10: 0 | K10: 0 | L10: 600000 | M10: 0 | N10: 0 | O10: 0 | P10: 0 | Q10: 0 | R10: 0 | S10: 0 | T10: 0 | U10: 0 | V10: 0 | W10: 0 | X10: 정상 | Y10: 1 | Z10: 1 | AA10: 0 | AB10: 0 | AG10: [일반지급신청] STOB 리그 팀활동지원비- 서울대학교 에피학 | AI10: [일반지급신청] STOB 리그 팀활동지원비- 서울대학교 에피학 | AJ10: N | AK10: N | AU10: 집행(이체) 완료 | AV10: N | AW10: 미등록 | AX10: 미확정 | BA10: 미확정 | BF10: 현금 | BG10: 증빙우선 | BH10: 건별지급
A11: 2025.12.24 | B11: 2025.12.24 | C11: 2025.12.22 | D11: 기타증빙 | E11: 직접비 | F11: 연구활동비 | G11: 연구활동비 기타비용 | H11: 600000 | I11: 600000 | J11: 0 | K11: 0 | L11: 600000 | M11: 0 | N11: 0 | O11: 0 | P11: 0 | Q11: 0 | R11: 0 | S11: 0 | T11: 0 | U11: 0 | V11: 0 | W11: 0 | X11: 정상 | Y11: 1 | Z11: 1 | AA11: 0 | AB11: 0 | AG11: [일반지급신청] STOB 리그 팀활동지원비- 서울대학교 에피학 | AI11: [일반지급신청] STOB 리그 팀활동지원비- 서울대학교 에피학 | AJ11: N | AK11: N | AU11: 집행(이체) 완료 | AV11: N | AW11: 미등록 | AX11: 미확정 | BA11: 미확정 | BF11: 현금 | BG11: 증빙우선 | BH11: 건별지급
A12: 2025.12.24 | B12: 2025.12.24 | C12: 2025.12.22 | D12: 기타증빙 | E12: 직접비 | F12: 연구활동비 | G12: 연구활동비 기타비용 | H12: 600000 | I12: 600000 | J12: 0 | K12: 0 | L12: 600000 | M12: 0 | N12: 0 | O12: 0 | P12: 0 | Q12: 0 | R12: 0 | S12: 0 | T12: 0 | U12: 0 | V12: 0 | W12: 0 | X12: 정상 | Y12: 1 | Z12: 1 | AA12: 0 | AB12: 0 | AG12: [일반지급신청] STOB 리그 팀활동지원비- 서울대학교 에피학 | AI12: [일반지급신청] STOB 리그 팀활동지원비- 서울대학교 에피학 | AJ12: N | AK12: N | AU12: 집행(이체) 완료 | AV12: N | AW12: 미등록 | AX12: 미확정 | BA12: 미확정 | BF12: 현금 | BG12: 증빙우선 | BH12: 건별지급
A13: 2025.12.24 | B13: 2025.12.24 | C13: 2025.12.22 | D13: 기타증빙 | E13: 직접비 | F13: 인건비 | G13: 참여연구원 인건비 | H13: 425360 | I13: 425360 | J13: 0 | K13: 0 | L13: 425360 | M13: 0 | N13: 0 | O13: 0 | P13: 0 | Q13: 0 | R13: 0 | S13: 0 | T13: 0 | U13: 0 | V13: 0 | W13: 0 | X13: 정상 | Y13: 1 | Z13: 1 | AA13: 0 | AB13: 0 | AG13: 기관부담금액(건강보험(기관)외 4건)[202512]한호철 등 4명 인 | AI13: 기관부담금액(건강보험(기관)외 4건)[202512]한호철 등 4명 인 | AJ13: N | AK13: N | AU13: 집행(이체) 완료 | AV13: N | AW13: 미등록 | AX13: 미확정 | BA13: 미확정 | BF13: 현금 | BG13: 증빙우선 | BH13: 건별지급
A14: 2025.12.24 | B14: 2025.12.24 | C14: 2025.12.22 | D14: 기타증빙 | E14: 직접비 | F14: 인건비 | G14: 참여연구원 인건비 | H14: 200870 | I14: 200870 | J14: 0 | K14: 0 | L14: 200870 | M14: 0 | N14: 0 | O14: 0 | P14: 0 | Q14: 0 | R14: 0 | S14: 0 | T14: 0 | U14: 0 | V14: 0 | W14: 0 | X14: 정상 | Y14: 1 | Z14: 1 | AA14: 0 | AB14: 0 | AG14: 공제금액(근로)(소득세외 1건)[202512]한호철 등 4명 인건비지 | AI14: 공제금액(근로)(소득세외 1건)[202512]한호철 등 4명 인건비지 | AJ14: N | AK14: N | AU14: 집행(이체) 완료 | AV14: N | AW14: 미등록 | AX14: 미확정 | BA14: 미확정 | BF14: 현금 | BG14: 증빙우선 | BH14: 건별지급
A15: 2025.12.24 | B15: 2025.12.24 | C15: 2025.12.22 | D15: 기타증빙 | E15: 직접비 | F15: 인건비 | G15: 참여연구원 인건비 | H15: 243050 | I15: 243050 | J15: 0 | K15: 0 | L15: 243050 | M15: 0 | N15: 0 | O15: 0 | P15: 0 | Q15: 0 | R15: 0 | S15: 0 | T15: 0 | U15: 0 | V15: 0 | W15: 0 | X15: 정상 | Y15: 1 | Z15: 1 | AA15: 0 | AB15: 0 | AG15: 퇴직적립금액(퇴직적립금)[202512]한호철 등 4명 인건비지급내 | AI15: 퇴직적립금액(퇴직적립금)[202512]한호철 등 4명 인건비지급내 | AJ15: N | AK15: N | AU15: 집행(이체) 완료 | AV15: N | AW15: 미등록 | AX15: 미확정 | BA15: 미확정 | BF15: 현금 | BG15: 증빙우선 | BH15: 건별지급
